File: unit_testing/Test sets/ppms_T479F.dat
[Header]
TITLE, T479F
FILEOPENTIME,1724092483.00,8/19/2024,2:34 PM
BYAPP, Resistivity, 2.0, 1.0
INFO, , Sample1 Name
INFO, 1, Sample1 Cross Section
INFO, 1, Sample1 Length
INFO, Ohm-m, Sample1 Units
INFO, , Sample2 Name
INFO, 1, Sample2 Cross Section
INFO, 1, Sample2 Length
INFO, Ohm-m, Sample2 Units
INFO, , Sample3 Name
INFO, 1, Sample3 Cross Section
INFO, 1, Sample3 Length
INFO, Ohm-m, Sample3 Units
INFO, , Sample4 Name
INFO, 1, Sample4 Cross Section
INFO, 1, Sample4 Length
INFO, Ohm-m, Sample4 Units
FIELDGROUP, Resistivity,2,3,4,5,6,7,8,9,10,11,12,13,14,15,16,17,18,19,20,21,22,23,24,25,26,27,28,29,30,31,32,33,34,35,36,37,38,39,40,41
STARTUPGROUP, Resistivity
STARTUPAXIS, X, 2, LINEAR, AUTO
STARTUPAXIS, Y1, 7, LINEAR, AUTO
STARTUPAXIS, Y2, 9, LINEAR, AUTO
STARTUPAXIS, Y3, 11, LINEAR, AUTO
PLOT_APPEARANCE, ALL, HORZ_GRID_ON, VERT_GRID_ON, MARKERS_AND_LINES, ALL_LINES
DATATYPE, TIME, 2
DATATYPE, COMMENT, 1
[Data]
Comment,Time Stamp (sec),Status (code),Temperature (K),Magnetic Field (Oe),Sample Position (degrees),Bridge 1 Resistivity (Ohm-m),Bridge 1 Excitation (uA),Bridge 2 Resistivity (Ohm-m),Bridge 2 Excitation (uA),Bridge 3 Resistivity (Ohm-m),Bridge 3 Excitation (uA),Bridge 4 Resistivity (Ohm-m),Bridge 4 Excitation (uA),Bridge 1 Std. Dev. (Ohm-m),Bridge 2 Std. Dev. (Ohm-m),Bridge 3 Std. Dev. (Ohm-m),Bridge 4 Std. Dev. (Ohm-m),Number of Readings,Bridge 1 Resistance (Ohms),Bridge 2 Resistance (Ohms),Bridge 3 Resistance (Ohms),Bridge 4 Resistance (Ohms)
,20098055.593,,18.0010552406311,-0.193977739661932,3.58732406867153e-042,8.30672119140625,1.20364344120026,8.34447143554688,1.19814336299896,8.33120166015625,1.20014333724976,,,1.20489871678288e-005,1.18875034926585e-005,1.25351274658852e-005,,4,8306.72119140625,8344.47143554688,8331.20166015625,
,20098226.468,,17.4298691749573,-0.120081456378102,3.58732406867153e-042,8.29934204101562,1.20364344120026,8.33701025390625,1.19814336299896,8.32375268554688,1.20014333724976,,,4.54622095693144e-005,4.84629382156186e-005,4.68819991524116e-005,,4,8299.34204101563,8337.01025390625,8323.75268554688,
,20098396.828,,16.8626642227173,-0.254018466919661,3.58732406867153e-042,8.28917797851563,1.20364344120026,8.32687890625,1.19814336299896,8.3136279296875,1.20014333724976,,,6.27640022730193e-005,5.79678383610018e-005,4.55755370725074e-005,,4,8289.17797851563,8326.87890625,8313.6279296875,
,20098566.281,,16.2979998588562,-0.277111060917377,3.58732406867153e-042,8.27560229492187,1.20364344120026,8.31314184570313,1.19814336299896,8.29991943359375,1.20014333724976,,,8.58498095035739e-005,7.36459708433443e-005,8.70689015127975e-005,,4,8275.60229492188,8313.14184570313,8299.91943359375,
,20098734.343,,15.7390379905701,0.0969888670369983,3.58732406867153e-042,8.25692993164063,1.20364344120026,8.29439501953125,1.19814336299896,8.28123168945313,1.20014333724976,,,0.000106208452641088,0.000107516139681901,0.000108013615766367,,4,8256.92993164063,8294.39501953125,8281.23168945313,
,20098904.156,,15.1732773780823,0.318677715957165,3.58732406867153e-042,8.22999780273438,1.20364344120026,8.26741870117188,1.19814336299896,8.25431982421875,1.20014333724976,,,0.000153764919903502,0.00015685668667476,0.000152460246042919,,4,8229.99780273438,8267.41870117188,8254.31982421875,
,20099073.187,,14.6097252368927,0.0184740698896348,3.58732406867153e-042,8.18978784179687,1.20364344120026,8.226892578125,1.19814336299896,8.21407055664062,1.20014333724976,,,0.000243532587307948,0.000247689078973952,0.000231206593792467,,4,8189.78784179688,8226.892578125,8214.07055664063,
,20099242.375,,14.0448987483978,0.0369481407105923,3.58732406867153e-042,8.12323107910156,1.20364344120026,8.15998718261719,1.19814336299896,8.14703955078125,1.20014333724976,,,0.000420151952985918,0.000429483856055792,0.000438844903583374,,4,8123.23107910156,8159.98718261719,8147.03955078125,
,20099411.515,,13.4811084270477,0.08313331566751,3.58732406867153e-042,7.98217504882813,1.20364344120026,8.01928771972656,1.19814336299896,8.00631164550781,1.20014333724976,,,0.00113713026781834,0.00114465339607927,0.00113296409698806,,4,7982.17504882813,8019.28771972656,8006.31164550781,
,20099580.64,,12.9180085659027,-0.249399952590466,3.58732406867153e-042,7.20247290039063,1.3016449213028,7.23881872558594,1.29564487934113,7.22800561523438,1.29739487171173,,,0.0128788195401763,0.0126162382274239,0.0129030027326276,,4,7202.47290039063,7238.81872558594,7228.00561523438,
,20099749.734,,12.3543789386749,-0.138555528596044,3.58732406867153e-042,5.52783375605941e-005,9.99890232086182,8.95227249711752e-005,9.86140060424805,3.54213723912835e-005,9.413893699646,,,6.6272176964628e-006,7.46496879699834e-006,3.17264244310999e-006,,4,0.0552783375605941,0.0895227249711752,0.0354213723912835,
,20099920.359,,11.7860226631165,-0.434140637516975,3.58732406867153e-042,4.10222768550739e-007,9.99890232086182,-2.7980565209873e-007,9.86140060424805,3.96118324715644e-007,9.413893699646,,,4.51181096036043e-007,1.88356759280926e-006,1.7279699948992e-006,,4,0.000410222768550739,-0.00027980565209873,0.000396118324715644,
,20100088.812,,11.2244122028351,-0.170885149389505,3.58732406867153e-042,1.49144398164935e-007,9.99890232086182,1.05127222195733e-006,9.86140060424805,-7.52639603888383e-007,9.413893699646,,,1.2032924414747e-006,2.50973437304046e-006,1.10034324406534e-006,,4,0.000149144398164935,0.00105127222195733,-0.000752639603888383,
,20100256.89,,10.663786649704,-0.193977735936642,3.58732406867153e-042,7.01130033121444e-007,9.99890232086182,-5.97505859332159e-007,9.86140060424805,1.15664758050116e-006,9.413893699646,,,9.37959646489447e-007,1.03640138737511e-006,6.8865996257932e-007,,4,0.000701130033121444,-0.000597505859332159,0.00115664758050116,
,20100427.265,,10.0968742370605,-0.0831333175301552,3.58732406867153e-042,1.02186612730293e-006,9.99890232086182,-1.54283864685567e-006,9.86140060424805,-4.04057474952424e-007,9.413893699646,,,7.41203833303097e-007,8.72305851337424e-007,1.80290713653654e-006,,4,0.00102186612730293,-0.00154283864685567,-0.000404057474952424,
,20100591.437,,9.51334714889526,0.300203643739223,3.58732406867153e-042,-2.17054571839981e-006,9.99890232086182,5.29579338035547e-008,9.86140060424805,8.63565537656541e-007,9.413893699646,,,1.43947438713474e-006,1.79091316725255e-006,1.68973198717967e-006,,4,-0.00217054571839981,5.29579338035546e-005,0.000863565537656541,
,20100767.89,,8.96926617622375,0.0692777642980218,3.58732406867153e-042,3.43136904120911e-007,9.99890232086182,6.05037588684354e-007,9.86140060424805,-1.53693692755041e-006,9.413893699646,,,1.10805883749809e-006,1.21834337746904e-006,9.78438437349485e-007,,4,0.000343136904120911,0.000605037588684354,-0.00153693692755041,
,20100936.453,,8.406658411026,-0.198596250265837,3.58732406867153e-042,7.4560557550285e-008,9.99890232086182,-8.31790894153528e-008,9.86140060424805,9.82381247013109e-007,9.413893699646,,,9.3314268956627e-007,7.83467472255188e-007,9.51252020999849e-007,,4,7.4560557550285e-005,-8.31790894153528e-005,0.000982381247013109,
,20101108.187,,7.84193515777588,0.0923703513108194,3.58732406867153e-042,1.06664433496917e-006,9.99890232086182,-5.44547960089403e-007,9.86140060424805,-3.96217219531536e-008,9.413893699646,,,9.81260591820244e-007,1.41034300863586e-006,1.13009889567893e-006,,4,0.00106664433496917,-0.000544547960089403,-3.96217219531536e-005,
,20101274.453,,7.27980148792267,0.078514798078686,3.58732406867153e-042,3.20736136927735e-007,9.99890232086182,2.79805695754476e-007,9.86140060424805,1.25965908227954e-006,9.413893699646,,,6.79172418145741e-007,1.99369399615728e-006,1.54146568738021e-006,,4,0.000320736136927735,0.000279805695754476,0.00125965908227954,
,20101444.14,,6.71527528762817,0.147792562842369,3.58732406867153e-042,9.99535192022449e-007,9.99890232086182,-4.08387330026017e-007,9.86140060424805,-7.20957017620094e-007,9.413893699646,,,1.29371793035001e-006,1.41721717589285e-006,1.1921074315594e-006,,4,0.000999535192022449,-0.000408387330026017,-0.000720957017620094,
,20101613.703,,6.14933347702026,0.295585125684738,3.58732406867153e-042,-1.71545156263164e-007,9.99890232086182,-8.16821950138547e-007,9.86140060424805,5.62494875339325e-007,9.413893699646,,,6.54143092510866e-007,1.30224971809909e-006,5.76297579162655e-007,,4,-0.000171545156263164,-0.000816821950138547,0.000562494875339326,
,20101782.078,,5.58838963508606,0.0923703517764807,3.58732406867153e-042,-1.41739546961617e-007,9.99890232086182,-3.47874163708184e-007,9.86140060424805,-3.17072854159051e-008,9.413893699646,,,1.42779722825501e-006,6.17221097650374e-007,7.07545224687341e-007,,4,-0.000141739546961617,-0.000347874163708184,-3.17072854159051e-005,
,20101951.453,,5.02421009540558,-0.212451804429293,3.58732406867153e-042,-1.19362093755626e-007,9.99890232086182,-2.34450286370702e-007,9.86140060424805,2.21851991227595e-007,9.413893699646,,,7.84592320015409e-007,7.32127199763842e-007,1.79780507881706e-006,,4,-0.000119362093755626,-0.000234450286370702,0.000221851991227595,
,20102121.359,,4.45786476135254,-0.406429544091225,3.58732406867153e-042,1.86424673302099e-007,9.99890232086182,-5.21882066095714e-007,9.86140060424805,3.08985123410821e-007,9.413893699646,,,7.18045646736561e-007,5.25880872605348e-007,6.9661737832796e-007,,4,0.000186424673302099,-0.000521882066095714,0.000308985123410821,
,20102289.921,,3.89585798978806,-0.129318492487073,3.58732406867153e-042,2.68529780441895e-007,9.99890232086182,6.88216627622751e-007,9.86140060424805,-1.66376557899639e-007,9.413893699646,,,9.74125146794168e-007,6.57744360832102e-007,1.87309391647782e-006,,4,0.000268529780441895,0.000688216627622751,-0.000166376557899639,
,20102459.421,,3.33099776506424,-0.180122181773186,3.58732406867153e-042,-6.19071492110379e-007,9.99890232086182,1.36160604597535e-007,9.86140060424805,-6.65481678879587e-007,9.413893699646,,,5.63887678512155e-007,3.78188853533407e-007,1.174885494061e-006,,4,-0.000619071492110379,0.000136160604597535,-0.000665481678879587,
,20103238.343,,17.7669496536255,20000.1772460938,3.58732406867153e-042,8.30506958007813,1.20264339447021,8.34281372070313,1.19739329814911,8.32955834960937,1.19914329051971,,,3.16995859242144e-005,2.01011748939543e-005,4.39203327616747e-005,,4,8305.06958007813,8342.81372070313,8329.55834960938,
,20103408.625,,17.2052459716797,20000.1586914063,3.58732406867153e-042,8.29696484375,1.20264339447021,8.3346376953125,1.19739329814911,8.32144775390625,1.19914329051971,,,4.82631289710706e-005,4.22808311147446e-005,2.70851795815142e-005,,4,8296.96484375,8334.6376953125,8321.44775390625,
,20103578.625,,16.6387476921082,20000.2631835938,3.58732406867153e-042,8.2859755859375,1.20264339447021,8.32359765625,1.19739329814911,8.31035546875,1.19914329051971,,,5.66321919769118e-005,5.94783876253536e-005,6.59812379674068e-005,,4,8285.9755859375,8323.59765625,8310.35546875,
,20103746.734,,16.0779247283936,20000.37890625,3.58732406867153e-042,8.27103857421875,1.20264339447021,8.30859155273438,1.19739329814911,8.295423828125,1.19914329051971,,,8.48500538451513e-005,7.42199181205281e-005,6.29146154705583e-005,,4,8271.03857421875,8308.59155273438,8295.423828125,
,20103916.031,,15.5139176845551,20000.3974609375,3.58732406867153e-042,8.25012841796875,1.20264339447021,8.28753344726563,1.19739329814911,8.2745185546875,1.19914329051971,,,0.000119983128388401,0.000118162746937965,0.000124910346936254,,4,8250.12841796875,8287.53344726563,8274.5185546875,
,20104085.796,,14.948317527771,20000.4340820313,3.58732406867153e-042,8.21988598632812,1.20264339447021,8.2571962890625,1.19739329814911,8.24408764648438,1.19914329051971,,,0.000167135462732533,0.000170053712443635,0.000163410674869017,,4,8219.88598632813,8257.1962890625,8244.08764648438,
,20104255.062,,14.3835594654083,20000.4897460938,3.58732406867153e-042,8.17315185546875,1.20264339447021,8.21018481445313,1.19739329814911,8.1974404296875,1.19914329051971,,,0.000323458234350354,0.000331653612526928,0.000316703748293487,,4,8173.15185546875,8210.18481445313,8197.4404296875,
,20104424.468,,13.8189215660095,20000.470703125,3.58732406867153e-042,8.09141247558594,1.20264339447021,8.12848022460938,1.19739329814911,8.11559606933594,1.19914329051971,,,0.000575374611490335,0.000565267574067813,0.000561971658036033,,4,8091.41247558594,8128.48022460938,8115.59606933594,
,20104593.5,,13.2567479610443,20000.5361328125,3.58732406867153e-042,7.89390832519531,1.20264339447021,7.9311220703125,1.19739329814911,7.91807946777344,1.19914329051971,,,0.0017129997574122,0.00175673160971411,0.00173417931971365,,4,7893.90832519531,7931.1220703125,7918.07946777344,
,20104763.125,,12.6920082569122,20000.6474609375,3.58732406867153e-042,6.5513974609375,1.49189782142639,6.58371130371094,1.46002233028412,6.56995739746094,1.48971030116081,,,0.0158681645845971,0.0154825375863708,0.0247429540566077,,4,6551.3974609375,6583.71130371094,6569.95739746094,
,20104932.875,,12.1260440349579,20000.638671875,3.58732406867153e-042,0.743429962158203,9.69639778137207,0.750571746826172,9.99890232086182,0.73045930480957,9.9364013671875,,,0.0140958351737544,0.013317938765854,0.0128969560637123,,4,743.429962158203,750.571746826172,730.45930480957,
,20105101.671,,11.5637109279633,20000.5961914063,3.58732406867153e-042,0.00498113167285919,9.69639778137207,0.00626411736011505,9.99890232086182,0.00490869748592377,9.9364013671875,,,0.000133183078937483,0.000173719186961293,0.000133531639259882,,4,4.98113167285919,6.26411736011505,4.90869748592377,
,20105270.875,,11.0013971328735,20000.642578125,3.58732406867153e-042,5.09185681585222e-006,9.69639778137207,7.87664030212909e-006,9.99890232086182,3.44517314806581e-006,9.9364013671875,,,9.37360236346878e-007,1.5710198918627e-006,5.4348123785284e-007,,4,0.00509185681585222,0.00787664030212909,0.00344517314806581,
,20105442.031,,10.4305939674377,20000.1997070313,3.58732406867153e-042,-1.1229967676627e-006,9.69639778137207,-8.42846275190823e-007,9.99890232086182,3.22753594446112e-007,9.9364013671875,,,1.10387602099864e-006,4.14136422814692e-007,6.73836196662389e-007,,4,-0.0011229967676627,-0.000842846275190823,0.000322753594446112,
,20105607.671,,9.87009859085083,20000.2583007813,3.58732406867153e-042,-4.99955443956424e-007,9.69639778137207,-1.04426688631065e-006,9.99890232086182,4.65361285023391e-007,9.9364013671875,,,2.00956361328408e-006,5.39950381633443e-007,2.9300883260475e-007,,4,-0.000499955443956424,-0.00104426688631065,0.000465361285023391,
,20105779.281,,9.30780386924744,20000.2905273438,3.58732406867153e-042,2.76883260085015e-007,9.69639778137207,3.431135774008e-007,9.99890232086182,1.13336327194702e-006,9.9364013671875,,,1.14972018634122e-006,1.23353598506515e-006,1.5436036646679e-006,,4,0.000276883260085015,0.0003431135774008,0.00113336327194702,
,20105942.39,,8.74435091018677,20000.12109375,3.58732406867153e-042,-1.69237107911613e-007,9.69639778137207,-6.04168679274153e-007,9.99890232086182,-1.57627652697556e-007,9.9364013671875,,,8.38235763608179e-007,7.36701663689389e-007,6.33842720613951e-007,,4,-0.000169237107911613,-0.000604168679274153,-0.000157627652697556,
,20106109.859,,8.17687463760376,20000.1997070313,3.58732406867153e-042,-2.53831636655377e-007,9.69639778137207,4.62452408100944e-007,9.99890232086182,8.25653100037016e-007,9.9364013671875,,,9.54846442837192e-007,1.06334798702745e-006,1.21097103688495e-006,,4,-0.000253831636655377,0.000462452408100944,0.000825653100037016,
,20106281.015,,7.61618530750275,20000.2265625,3.58732406867153e-042,2.38439919485245e-007,9.69639778137207,1.68569256493356e-006,9.99890232086182,-1.36606735759415e-006,9.9364013671875,,,2.87294763287911e-007,8.29381525902363e-007,1.16676013523218e-006,,4,0.000238439919485245,0.00168569256493356,-0.00136606735759415,
,20106449.828,,7.0525324344635,20000.12109375,3.58732406867153e-042,-3.99993161408929e-007,9.69639778137207,-4.32600259955507e-007,9.99890232086182,4.50364705102401e-008,9.9364013671875,,,1.00004891833212e-006,9.41003941069007e-007,1.48633888926131e-006,,4,-0.000399993161408929,-0.000432600259955507,4.50364705102402e-005,
,20106619.218,,6.48930263519287,20000.2353515625,3.58732406867153e-042,3.84601400583051e-007,9.69639778137207,2.46152284489654e-007,9.99890232086182,-3.00235355098266e-007,9.9364013671875,,,1.28639715974255e-006,7.89762723227028e-007,6.50897968006429e-007,,4,0.000384601400583051,0.000246152284489654,-0.000300235355098266,
,20106788.109,,5.92592287063599,20000.2578125,3.58732406867153e-042,-2.23072178414441e-007,9.69639778137207,-3.50588285073172e-007,9.99890232086182,-7.20560168701923e-007,9.9364013671875,,,7.37853898259241e-007,1.05366024268085e-006,9.50156422655423e-007,,4,-0.000223072178414441,-0.000350588285073172,-0.000720560168701923,
,20106957.453,,5.36182498931885,20000.2309570313,3.58732406867153e-042,4.46096346422564e-007,9.69639778137207,-1.93922649486922e-007,9.99890232086182,2.47700620093383e-007,9.9364013671875,,,6.35919563165971e-007,1.57884333970744e-006,5.64262152017705e-007,,4,0.000446096346422564,-0.000193922649486922,0.000247700620093383,
,20107126.843,,4.79623258113861,20000.177734375,3.58732406867153e-042,3.07666734443046e-007,9.69639778137207,-1.21578877406137e-006,9.99890232086182,6.75547344144434e-008,9.9364013671875,,,8.29021400245701e-007,6.82790009170497e-007,1.94255740764171e-006,,4,0.000307666734443046,-0.00121578877406137,6.75547344144434e-005,
,20107295.437,,4.23471963405609,20000.1909179688,3.58732406867153e-042,-1.59219272973132e-006,9.69639778137207,-2.90930500341346e-007,9.99890232086182,-1.11086842662189e-006,9.9364013671875,,,1.22574317945642e-006,2.09523246929616e-006,6.99930627838532e-007,,4,-0.00159219272973132,-0.000290930500341346,-0.00111086842662189,
,20107464.968,,3.66965860128403,20000.2177734375,3.58732406867153e-042,-2.13059154339135e-006,9.69639778137207,2.53603673627367e-007,9.99890232086182,-3.52746661519632e-007,9.9364013671875,,,1.78159714600111e-006,6.43532723481172e-007,1.29977611197038e-006,,4,-0.00213059154339135,0.000253603673627367,-0.000352746661519632,
,20107633.937,,3.10652911663055,20000.1772460938,3.58732406867153e-042,-1.74599007004872e-006,9.69639778137207,5.74363104533404e-007,9.99890232086182,6.2296549367602e-007,9.9364013671875,,,5.49211495478595e-007,2.08184704181263e-007,1.30790130430191e-006,,4,-0.00174599007004872,0.000574363104533404,0.00062296549367602,
,20108422.546,,17.540997505188,40000.61328125,3.58732406867153e-042,8.30535620117188,1.20239341259003,8.34310302734375,1.19689333438873,8.32980004882812,1.19889330863953,,,4.71558258677617e-005,6.63217322840617e-005,3.74573343537232e-005,,4,8305.35620117188,8343.10302734375,8329.80004882813,
,20108591.89,,16.9774188995361,40000.3076171875,3.58732406867153e-042,8.29701342773438,1.20239341259003,8.33465405273438,1.19689333438873,8.32145288085938,1.19889330863953,,,5.07312215819475e-005,7.26353460779011e-005,3.8727610531727e-005,,4,8297.01342773438,8334.65405273438,8321.45288085938,
,20108761.421,,16.4137749671936,40000.421875,3.58732406867153e-042,8.28566918945313,1.20239341259003,8.323298828125,1.19689333438873,8.31009130859375,1.19889330863953,,,4.93205295406008e-005,6.45456383765542e-005,6.00664606314366e-005,,4,8285.66918945313,8323.298828125,8310.09130859375,
,20108930.453,,15.8505010604858,40000.4609375,3.58732406867153e-042,8.270087890625,1.20239341259003,8.3077021484375,1.19689333438873,8.2945224609375,1.19889330863953,,,9.68842286261558e-005,9.27657401672276e-005,8.94954561385876e-005,,4,8270.087890625,8307.7021484375,8294.5224609375,
,20109100.281,,15.28582239151,40000.673828125,3.58732406867153e-042,8.2482158203125,1.20239341259003,8.28563208007813,1.19689333438873,8.27260766601563,1.19889330863953,,,0.000146277473329178,0.000124149020685909,0.000120518174510377,,4,8248.2158203125,8285.63208007813,8272.60766601563,
,20109269.968,,14.7193529605865,40000.53515625,3.58732406867153e-042,8.21607934570313,1.20239341259003,8.25331909179688,1.19689333438873,8.240453125,1.19889330863953,,,0.000167161096096583,0.000149200653326848,0.000172139741370382,,4,8216.07934570313,8253.31909179688,8240.453125,
,20109438.531,,14.1589789390564,40000.572265625,3.58732406867153e-042,8.16600341796875,1.20239341259003,8.2031953125,1.19689333438873,8.19027661132812,1.19889330863953,,,0.000293103402851965,0.000293754620864519,0.000293281988113484,,4,8166.00341796875,8203.1953125,8190.27661132813,
,20109607.156,,13.5968425273895,40000.255859375,3.58732406867153e-042,8.07548254394531,1.20239341259003,8.11198413085938,1.19689333438873,8.09922680664063,1.19889330863953,,,0.000454642210163602,0.000493897192838894,0.000498673147683823,,4,8075.48254394531,8111.98413085938,8099.22680664063,
,20109774.875,,13.0334043502808,40000.2802734375,3.58732406867153e-042,7.83765258789063,1.20239341259003,7.87340966796875,1.19689333438873,7.86128210449219,1.19889330863953,,,0.000894297570746642,0.00112265793530104,0.000920864798481337,,4,7837.65258789063,7873.40966796875,7861.28210449219,
,20109946.156,,12.4666848182678,40000.3671875,3.58732406867153e-042,6.21617053222656,1.52114832401276,6.2430380859375,1.51464819908142,6.24144494628906,1.51839828491211,,,0.0176734687006893,0.0177800768545842,0.0175708874917707,,4,6216.17053222656,6243.0380859375,6241.44494628906,
,20110115.843,,11.8834404945374,40000.443359375,3.58732406867153e-042,0.625315292358398,9.74139881134033,0.648090301513672,9.85389995574951,0.626026565551758,9.68139743804932,,,0.0108315307231563,0.0182629047211926,0.0143980795803868,,4,625.315292358398,648.090301513672,626.026565551758,
,20110284.656,,11.3386251926422,40000.451171875,3.58732406867153e-042,0.0062358683347702,9.74139881134033,0.00765678524971008,9.85389995574951,0.00590461242198944,9.68139743804932,,,0.000270883120516946,0.000303766949236719,0.000244428919941204,,4,6.2358683347702,7.65678524971008,5.90461242198944,
,20110453.718,,10.7765309810638,40000.5166015625,3.58732406867153e-042,9.80752590112388e-006,9.74139881134033,1.73853519372642e-005,9.85389995574951,9.83752612955868e-006,9.68139743804932,,,7.54634148661272e-007,1.50592759057312e-006,1.86689914766979e-006,,4,0.00980752590112388,0.0173853519372642,0.00983752612955868,
,20110622.218,,10.2122228145599,40000.5263671875,3.58732406867153e-042,1.37790106236935e-007,9.74139881134033,6.88764164806344e-007,9.85389995574951,-2.30873010877986e-008,9.68139743804932,,,1.76329078292604e-006,1.09123582059324e-006,1.57385340558651e-006,,4,0.000137790106236935,0.000688764164806344,-2.30873010877986e-005,
,20110793.484,,9.63465857505798,40000.5166015625,3.58732406867153e-042,-5.97170197579544e-007,9.74139881134033,-2.87626971839927e-007,9.85389995574951,-5.93151416978799e-007,9.68139743804932,,,1.34146504805037e-006,9.00520496382669e-007,9.10036181448003e-007,,4,-0.000597170197579544,-0.000287626971839927,-0.000593151416978799,
,20110950.093,,9.10732078552246,40000.576171875,3.58732406867153e-042,-3.29190541378921e-007,9.74139881134033,-3.9355249464279e-007,9.85389995574951,1.23254956815799e-006,9.68139743804932,,,4.36550984279791e-007,9.99348189165212e-007,1.55832280234539e-006,,4,-0.000329190541378921,-0.00039355249464279,0.00123254956815799,
,20111124.203,,8.52027010917664,40000.5908203125,3.58732406867153e-042,-4.05745959142223e-007,9.74139881134033,1.74093112946139e-007,9.85389995574951,-5.39425309398211e-008,9.68139743804932,,,2.3015655633876e-006,4.0978353724971e-007,9.88538999654298e-007,,4,-0.000405745959142223,0.000174093112946139,-5.39425309398212e-005,
,20111294.39,,7.95601677894592,40000.599609375,3.58732406867153e-042,6.35435973890708e-007,9.74139881134033,-1.13531487295404e-006,9.85389995574951,1.15580849524122e-007,9.68139743804932,,,6.56246922133484e-007,1.76967065855205e-006,1.13246154383842e-006,,4,0.000635435973890708,-0.00113531487295404,0.000115580849524122,
,20111463.14,,7.39126372337341,40000.6689453125,3.58732406867153e-042,8.65173788042739e-007,9.74139881134033,-6.73618422297295e-007,9.85389995574951,1.54059674969176e-007,9.68139743804932,,,1.35536641105189e-006,1.36764123596082e-006,5.62336757817828e-007,,4,0.000865173788042739,-0.000673618422297295,0.000154059674969176,
,20111633.14,,6.82441604137421,40000.6416015625,3.58732406867153e-042,-4.59380098618567e-008,9.74139881134033,3.48162568116095e-007,9.85389995574951,-3.62085942470003e-007,9.68139743804932,,,1.90787597280251e-006,1.77854919422004e-006,1.33222367367701e-006,,4,-4.59380098618567e-005,0.000348162568116095,-0.000362085942470003,
,20111801.234,,6.26440834999084,40000.6318359375,3.58732406867153e-042,-2.14393319765804e-007,9.74139881134033,-7.58467240302708e-009,9.85389995574951,7.62626728828764e-007,9.68139743804932,,,7.1393667043008e-007,2.88292632645564e-007,1.91051304132081e-006,,4,-0.000214393319765804,-7.58467240302707e-006,0.000762626728828764,
,20111970.75,,5.70080864429474,40000.4521484375,3.58732406867153e-042,-9.95721857179887e-008,9.74139881134033,-9.99074283754453e-007,9.85389995574951,1.84890857781284e-007,9.68139743804932,,,3.66451006373531e-007,1.28855989453708e-006,1.46133568637886e-007,,4,-9.95721857179888e-005,-0.000999074283754453,0.000184890857781284,
,20112139.89,,5.13751626014709,40000.4091796875,3.58732406867153e-042,-4.89997470140224e-007,9.74139881134033,-1.36240625579376e-007,9.85389995574951,4.08284628065303e-007,9.68139743804932,,,7.99197243405506e-007,4.56400415832799e-007,6.25229796224779e-007,,4,-0.000489997470140224,-0.000136240625579376,0.000408284628065303,
,20112309.593,,4.57083213329315,40000.494140625,3.58732406867153e-042,-2.67955794697627e-007,9.74139881134033,-1.05949177850562e-007,9.85389995574951,4.23700206738431e-007,9.68139743804932,,,8.84496880747795e-007,8.53207735190985e-007,1.45045546435264e-006,,4,-0.000267955794697627,-0.000105949177850562,0.000423700206738431,
,20112478.968,,4.00587320327759,40000.439453125,3.58732406867153e-042,-1.14845024654642e-007,9.74139881134033,-7.94689694885165e-007,9.85389995574951,3.77477503207047e-007,9.68139743804932,,,8.19564406293823e-007,1.64312167455787e-006,1.15837558055817e-006,,4,-0.000114845024654642,-0.000794689694885165,0.000377477503207047,
,20112647.562,,3.44423770904541,40000.42578125,3.58732406867153e-042,-4.97669709147885e-007,9.74139881134033,2.72481243882794e-007,9.85389995574951,-3.08143433358055e-007,9.68139743804932,,,1.85898610643568e-006,7.7393922907237e-007,1.14534854819065e-006,,4,-0.000497669709147885,0.000272481243882794,-0.000308143433358055,
,20113423.921,,17.8724870681763,60000.33203125,3.58732406867153e-042,8.3134150390625,1.20189332962036,8.35115258789063,1.19664335250854,8.33793579101562,1.19839334487915,,,2.12500381042072e-005,2.73119383211018e-005,3.18799609084111e-005,,4,8313.4150390625,8351.15258789063,8337.93579101563,
,20113601.953,,17.313542842865,60000.578125,3.58732406867153e-042,8.3074501953125,1.20189332962036,8.345185546875,1.19664335250854,8.33189477539063,1.19839334487915,,,6.15505626174587e-005,5.76501103625001e-005,4.35001214993411e-005,,4,8307.4501953125,8345.185546875,8331.89477539063,
,20113770.75,,16.7541127204895,60000.2646484375,3.58732406867153e-042,8.2992861328125,1.20189332962036,8.336974609375,1.19664335250854,8.32376977539063,1.19839334487915,,,4.81246883158802e-005,5.66488765271379e-005,2.71985340239976e-005,,4,8299.2861328125,8336.974609375,8323.76977539063,
,20113940.75,,16.1870985031128,60000.447265625,3.58732406867153e-042,8.28810180664063,1.20189332962036,8.32571606445313,1.19664335250854,8.31254028320313,1.19839334487915,,,7.68678100882305e-005,7.73871230618496e-005,7.5437066363674e-005,,4,8288.10180664063,8325.71606445313,8312.54028320313,
,20114109.078,,15.6266541481018,60000.6201171875,3.58732406867153e-042,8.27286279296875,1.20189332962036,8.310431640625,1.19664335250854,8.2972646484375,1.19839334487915,,,8.49819271642873e-005,9.89200092561998e-005,8.99021423413353e-005,,4,8272.86279296875,8310.431640625,8297.2646484375,
,20114278.671,,15.0611109733582,60000.57421875,3.58732406867153e-042,8.25120166015625,1.20189332962036,8.28868872070312,1.19664335250854,8.2755927734375,1.19839334487915,,,0.000123382651283222,0.000126978319611346,0.000137681465543719,,4,8251.20166015625,8288.68872070313,8275.5927734375,
,20114448.296,,14.4966130256653,60000.6904296875,3.58732406867153e-042,8.21921459960937,1.20189332962036,8.256435546875,1.19664335250854,8.2435986328125,1.19839334487915,,,0.000202067517100189,0.000205615706061941,0.000191524554683668,,4,8219.21459960938,8256.435546875,8243.5986328125,
,20114617.656,,13.9325468540192,60000.33203125,3.58732406867153e-042,8.16859497070313,1.20189332962036,8.20549877929687,1.19664335250854,8.19261157226563,1.19839334487915,,,0.00029664931703928,0.000297650103649011,0.000291128952619976,,4,8168.59497070313,8205.49877929688,8192.61157226563,
,20114786.343,,13.3696973323822,60000.400390625,3.58732406867153e-042,8.07474670410156,1.20189332962036,8.11101794433594,1.19664335250854,8.09845458984375,1.19839334487915,,,0.000529784752476446,0.000550949987629494,0.000544878239276453,,4,8074.74670410156,8111.01794433594,8098.45458984375,
,20114956.843,,12.8021862506866,60000.50390625,3.58732406867153e-042,7.81486633300781,1.20189332962036,7.8491455078125,1.19664335250854,7.83713684082031,1.19839334487915,,,0.00205664344751717,0.00205408626059846,0.00209919813706167,,4,7814.86633300781,7849.1455078125,7837.13684082031,
,20115125.406,,12.2399985790253,60000.5458984375,3.58732406867153e-042,6.01235327148438,1.64615023136139,6.05578295898438,1.64040005207062,6.04039868164063,1.61221215128899,,,0.0238322648713643,0.0270946930772186,0.0263892352221293,,4,6012.35327148438,6055.78295898438,6040.39868164063,
,20115293.312,,11.6440515518188,60000.53515625,3.58732406867153e-042,0.55134211730957,9.34889221191406,0.571010498046875,9.36889266967773,0.560987060546875,9.55639553070068,,,0.0138062212037137,0.0295129077287183,0.0175854084495842,,4,551.34211730957,571.010498046875,560.987060546875,
,20115464.765,,11.1107025146484,60000.6005859375,3.58732406867153e-042,0.00639013671875,9.34889221191406,0.00799643754959106,9.36889266967773,0.00639173054695129,9.55639553070068,,,0.000165318178465919,0.000211114249565267,0.000174045070265534,,4,6.39013671875,7.99643754959106,6.39173054695129,
,20115633.656,,10.4981100559235,60000.6474609375,3.58732406867153e-042,1.09851050656289e-005,9.34889221191406,1.5753885731101e-005,9.36889266967773,1.08402101323009e-005,9.55639553070068,,,1.16667396450571e-006,3.63001544909327e-006,1.17892818865788e-006,,4,0.0109851050656289,0.015753885731101,0.0108402101323009,
,20115798.375,,9.94396615028381,60000.693359375,3.58732406867153e-042,-5.42497407877818e-007,9.34889221191406,1.06669911838253e-006,9.36889266967773,-4.13625151850283e-007,9.55639553070068,,,1.21321871278202e-006,2.14672094383246e-006,7.5577677999121e-007,,4,-0.000542497407877818,0.00106669911838253,-0.000413625151850283,
,20115971.234,,9.41890144348145,60000.70703125,3.58732406867153e-042,-1.03707831294741e-006,9.34889221191406,6.05008732236456e-007,9.36889266967773,-2.49729506322183e-007,9.55639553070068,,,1.10870880084653e-006,1.10880157764342e-006,8.22682103548852e-007,,4,-0.00103707831294741,0.000605008732236456,-0.000249729506322183,
,20116135.25,,8.8573784828186,60000.5458984375,3.58732406867153e-042,2.39358327235095e-007,9.34889221191406,-6.05008710408583e-007,9.36889266967773,-7.17978437023703e-007,9.55639553070068,,,1.55619264880992e-006,1.5659382136897e-006,1.55378463937447e-006,,4,0.000239358327235095,-0.000605008710408583,-0.000717978437023703,
,20116304.656,,8.2936155796051,60000.5458984375,3.58732406867153e-042,-4.70672490337165e-007,9.34889221191406,1.27363717183471e-007,9.36889266967773,-5.46310708159581e-007,9.55639553070068,,,9.49159150283936e-007,1.22308958120397e-006,1.36598192823048e-006,,4,-0.000470672490337165,0.000127363717183471,-0.000546310708159581,
,20116474.156,,7.73051559925079,60000.568359375,3.58732406867153e-042,-6.38205849099904e-007,9.34889221191406,3.26399047480663e-007,9.36889266967773,-7.01922836015001e-008,9.55639553070068,,,1.21445155028228e-006,6.24583605090885e-007,9.41290885220319e-007,,4,-0.000638205849099904,0.000326399047480663,-7.01922836015001e-005,
,20116643.343,,7.16434121131897,60000.5595703125,3.58732406867153e-042,-3.90902947401628e-007,9.34889221191406,-3.18396887450945e-007,9.36889266967773,-3.12344445774215e-008,9.55639553070068,,,9.44848566446918e-007,1.29050860087334e-006,1.22586183765532e-006,,4,-0.000390902947401628,-0.000318396887450945,-3.12344445774215e-005,
,20116811.703,,6.60299706459045,60000.6279296875,3.58732406867153e-042,-1.99441197037231e-006,9.34889221191406,-9.23430490729515e-007,9.36889266967773,-2.88760415969591e-007,9.55639553070068,,,8.69635458431554e-007,9.4052632814756e-007,8.88519400212326e-007,,4,-0.00199441197037231,-0.000923430490729515,-0.000288760415969591,
,20116981.828,,6.03637933731079,60000.634765625,3.58732406867153e-042,-5.50466880667955e-007,9.34889221191406,1.67175749083981e-007,9.36889266967773,-7.96040218119742e-007,9.55639553070068,,,2.14489889346283e-006,1.29916893873535e-006,1.21596713269866e-006,,4,-0.000550466880667955,0.000167175749083981,-0.000796040218119742,
,20117150.64,,5.47385156154633,60000.6611328125,3.58732406867153e-042,-1.62741751410067e-006,9.34889221191406,1.91082883247873e-007,9.36889266967773,2.10722973861266e-007,9.55639553070068,,,5.74876913166273e-007,1.12173044541236e-006,8.80304862969082e-007,,4,-0.00162741751410067,0.000191082883247873,0.000210722973861266,
,20117319.625,,4.91068065166473,60000.69921875,3.58732406867153e-042,9.57333941187244e-008,9.34889221191406,1.67150894412771e-007,9.36889266967773,-1.32685590870096e-007,9.55639553070068,,,7.2731413639608e-007,1.45347443867457e-006,1.63338556735637e-006,,4,9.57333941187244e-005,0.000167150894412771,-0.000132685590870096,
,20117488.984,,4.34618937969208,60000.197265625,3.58732406867153e-042,4.78641959489323e-007,9.34889221191406,-2.46799827436917e-007,9.36889266967773,9.9117033823859e-007,9.55639553070068,,,1.70489399768547e-006,8.19362830102542e-007,1.68548335727577e-006,,4,0.000478641959489323,-0.000246799827436917,0.000991170338238589,
,20117658.5,,3.78088146448135,60000.2109375,3.58732406867153e-042,8.45611521071987e-007,9.34889221191406,3.42328828992322e-007,9.36889266967773,-1.66232137416955e-006,9.55639553070068,,,1.96405403451876e-006,1.80214793457839e-006,1.3261931343975e-006,,4,0.000845611521071987,0.000342328828992322,-0.00166232137416955,
,20117827.093,,3.21880227327347,60000.26171875,3.58732406867153e-042,5.50417084014043e-007,9.34889221191406,4.6169036795618e-007,9.36889266967773,-9.83373931376264e-007,9.55639553070068,,,6.54098424442357e-007,8.53924596745502e-007,1.08602167481379e-006,,4,0.000550417084014043,0.00046169036795618,-0.000983373931376264,
,20118607.187,,17.6529331207275,80000.541015625,3.58732406867153e-042,8.31658251953125,1.20139336585999,8.3543896484375,1.19614326953888,8.34107446289062,1.19789338111877,,,1.6478932694589e-005,2.11034114758661e-005,2.65239999534533e-005,,4,8316.58251953125,8354.3896484375,8341.07446289063,
,20118776.328,,17.091356754303,80000.59375,3.58732406867153e-042,8.310953125,1.20139336585999,8.34869653320312,1.19614326953888,8.33545043945313,1.19789338111877,,,5.25938632219068e-005,4.51884979457331e-005,4.7673581953863e-005,,4,8310.953125,8348.69653320313,8335.45043945313,
,20118946.531,,16.5255327224731,80000.3515625,3.58732406867153e-042,8.303234375,1.20139336585999,8.34098291015625,1.19614326953888,8.327681640625,1.19789338111877,,,5.10481682668455e-005,6.73811989575719e-005,4.66044292295996e-005,,4,8303.234375,8340.98291015625,8327.681640625,
,20119115.453,,15.9622285366058,80000.591796875,3.58732406867153e-042,8.292767578125,1.20139336585999,8.33038916015625,1.19614326953888,8.3172080078125,1.19789338111877,,,7.82531582286846e-005,4.86544796428146e-005,6.64384076028191e-005,,4,8292.767578125,8330.38916015625,8317.2080078125,
,20119284.484,,15.398668050766,80000.50390625,3.58732406867153e-042,8.27832080078125,1.20139336585999,8.31587548828125,1.19614326953888,8.30268725585938,1.19789338111877,,,6.50516911997495e-005,7.66632522062537e-005,9.22693762564223e-005,,4,8278.32080078125,8315.87548828125,8302.68725585938,
,20119454.015,,14.8354253768921,80000.70703125,3.58732406867153e-042,8.2577783203125,1.20139336585999,8.29520385742187,1.19614326953888,8.2820947265625,1.19789338111877,,,0.0001378423876062,0.000137515808299773,0.000144133200720543,,4,8257.7783203125,8295.20385742188,8282.0947265625,
,20119623.218,,14.2472424507141,80000.4921875,3.58732406867153e-042,8.226396484375,1.20139336585999,8.26374194335938,1.19614326953888,8.250748046875,1.19789338111877,,,0.000239943396682697,0.000399409492695999,0.000249760560017136,,4,8226.396484375,8263.74194335938,8250.748046875,
,20119792.359,,13.7063407897949,80000.501953125,3.58732406867153e-042,8.17887097167969,1.20139336585999,8.21579345703125,1.19614326953888,8.20320678710938,1.19789338111877,,,0.00026659717756528,0.000269241404959003,0.000269192525233086,,4,8178.87097167969,8215.79345703125,8203.20678710938,
,20119961.515,,13.1431646347046,80000.68359375,3.58732406867153e-042,8.08859326171875,1.20139336585999,8.124767578125,1.19614326953888,8.11230773925781,1.19789338111877,,,0.000639281297536169,0.00064758529461355,0.000623020137699602,,4,8088.59326171875,8124.767578125,8112.30773925781,
,20120130.75,,12.5793409347534,80000.462890625,3.58732406867153e-042,7.84221166992188,1.20139336585999,7.87597265625,1.19614326953888,7.86426086425781,1.19789338111877,,,0.00255756259583494,0.002514683040134,0.00247590634288282,,4,7842.21166992188,7875.97265625,7864.26086425781,
,20120300.093,,12.0155732631683,80000.611328125,3.58732406867153e-042,6.14758020019531,1.51989829540253,6.16676489257813,1.51564812660217,6.15793579101563,1.5186482667923,,,0.0176871336553405,0.0162252189526564,0.0146311640117778,,4,6147.58020019531,6166.76489257813,6157.93579101563,
,20120469.218,,11.4510669708252,80000.57421875,3.58732406867153e-042,0.775976165771484,9.75889873504639,0.781978820800781,9.73639869689941,0.785515777587891,9.82390022277832,,,0.0120285843146036,0.0117373508429726,0.0125057161124679,,4,775.976165771484,781.978820800781,785.515777587891,
,20120638.718,,10.8863115310669,80000.255859375,3.58732406867153e-042,0.0103324089050293,9.75889873504639,0.0120293614864349,9.73639869689941,0.00983070993423462,9.82390022277832,,,0.000298228805142402,0.000345481886579764,0.000281194392276143,,4,10.3324089050293,12.0293614864349,9.83070993423462,
,20120805.687,,10.3241798877716,80000.232421875,3.58732406867153e-042,3.23960985988379e-005,9.75889873504639,4.59296777844429e-005,9.73639869689941,3.08683607727289e-005,9.82390022277832,,,2.20996434393906e-006,8.43285012352313e-007,8.30655025299816e-007,,4,0.0323960985988379,0.0459296777844429,0.0308683607727289,
,20120975.375,,9.77785325050354,80000.3359375,3.58732406867153e-042,-1.91057188203558e-007,9.75889873504639,-1.04178833134938e-006,9.73639869689941,6.83046237099916e-008,9.82390022277832,,,5.58836540633231e-007,1.2549281490425e-006,9.25942914034375e-007,,4,-0.000191057188203558,-0.00104178833134938,6.83046237099916e-005,
,20121146.875,,9.19595718383789,80000.365234375,3.58732406867153e-042,-8.33059883007081e-007,9.75889873504639,1.38647646235768e-006,9.73639869689941,-1.18433407624252e-006,9.82390022277832,,,1.40941207930219e-006,9.06452213727111e-007,5.52069976301716e-007,,4,-0.000833059883007081,0.00138647646235768,-0.00118433407624252,
,20121309.031,,8.63227963447571,80000.478515625,3.58732406867153e-042,1.52693173731677e-008,9.75889873504639,-2.02226263354532e-006,9.73639869689941,1.22986262431368e-006,9.82390022277832,,,7.12187037166994e-007,2.03832576726894e-006,1.45091473473838e-006,,4,1.52693173731677e-005,-0.00202226263354532,0.00122986262431368,
,20121476.39,,8.06855845451355,80000.455078125,3.58732406867153e-042,3.13354801619425e-007,9.75889873504639,3.83021324523725e-007,9.73639869689941,-9.86885570455342e-008,9.82390022277832,,,1.35895035590977e-006,5.17502164311336e-007,1.72434740154667e-006,,4,0.000313354801619425,0.000383021324523725,-9.86885570455343e-005,
,20121647.015,,7.5045508146286,80000.42578125,3.58732406867153e-042,-5.19681270816363e-007,9.75889873504639,-3.60016612830805e-007,9.73639869689941,6.83259611832909e-007,9.82390022277832,,,1.59036880683118e-006,1.59614977779118e-006,1.52300633501369e-006,,4,-0.000519681270816363,-0.000360016612830805,0.000683259611832909,
,20121816.312,,6.94204461574554,80000.4765625,3.58732406867153e-042,-5.19705121405423e-007,9.75889873504639,8.42948211356997e-008,9.73639869689941,3.87193882488646e-007,9.82390022277832,,,1.18334098076092e-006,1.30863008272013e-006,1.46244491638223e-006,,4,-0.000519705121405423,8.42948211356997e-005,0.000387193882488646,
,20121985.953,,6.37668752670288,80000.46875,3.58732406867153e-042,-5.42609108379111e-007,9.75889873504639,2.29808010772103e-007,9.73639869689941,-1.74601047547185e-007,9.82390022277832,,,1.32623062177186e-006,1.1868141182286e-006,1.10651203917297e-006,,4,-0.000542609108379111,0.000229808010772103,-0.000174601047547185,
,20122155.89,,5.81240355968475,80000.529296875,3.58732406867153e-042,8.0244972195942e-007,9.75889873504639,2.83421903077397e-007,9.73639869689941,1.51919812196866e-008,9.82390022277832,,,3.20877020340844e-007,7.62726435991919e-007,1.57111263298406e-006,,4,0.00080244972195942,0.000283421903077397,1.51919812196866e-005,
,20122324.718,,5.24729597568512,80000.48046875,3.58732406867153e-042,8.40289139887318e-008,9.75889873504639,9.65169705523294e-007,9.73639869689941,-7.44003784348024e-007,9.82390022277832,,,2.03770638872758e-006,1.41154829076403e-006,1.14966164461495e-006,,4,8.40289139887318e-005,0.000965169705523294,-0.000744003784348024,
,20122494.187,,4.68208730220795,80000.541015625,3.58732406867153e-042,-1.2456890399335e-006,9.75889873504639,1.02645978404325e-006,9.73639869689941,1.13117403816432e-006,9.82390022277832,,,1.42822986769674e-006,1.01960324340109e-006,2.00510039766121e-006,,4,-0.0012456890399335,0.00102645978404325,0.00113117403816432,
,20122662.265,,4.1224889755249,80000.55078125,3.58732406867153e-042,-1.19983342301566e-006,9.75889873504639,-2.37436404859182e-007,9.73639869689941,-1.2526623904705e-006,9.82390022277832,,,1.21657458116695e-006,6.72856793992611e-007,4.89361472053729e-007,,4,-0.00119983342301566,-0.000237436404859181,-0.0012526623904705,
,20122832.218,,3.55680787563324,80000.537109375,3.58732406867153e-042,1.14639075036393e-007,9.75889873504639,2.22131799091585e-007,9.73639869689941,-2.04961292183725e-007,9.82390022277832,,,1.83817986941191e-006,5.37867031571256e-007,4.14938112564164e-007,,4,0.000114639075036393,0.000222131799091585,-0.000204961292183725,
,20123626.703,,17.9990983009338,100000.54296875,3.58732406867153e-042,8.32425903320313,1.20089340209961,8.362083984375,1.19539332389832,8.34876635742187,1.19739329814911,,,1.27771005697005e-005,1.71810323945965e-005,1.63759897206421e-005,,4,8324.25903320313,8362.083984375,8348.76635742188,
,20123794.656,,17.4403376579285,100000.451171875,3.58732406867153e-042,8.32066674804688,1.20089340209961,8.35848852539062,1.19539332389832,8.34520678710937,1.19739329814911,,,9.22236225001404e-006,2.03607233111172e-005,1.23604570725818e-005,,4,8320.66674804688,8358.48852539063,8345.20678710938,
,20123967.515,,16.8618593215942,100000.298828125,3.58732406867153e-042,8.31554077148438,1.20089340209961,8.3532841796875,1.19539332389832,8.34003588867188,1.19739329814911,,,2.77537557481523e-005,3.30521594661595e-005,3.13821709490107e-005,,4,8315.54077148438,8353.2841796875,8340.03588867188,
,20124136.468,,16.3008580207825,100000.552734375,3.58732406867153e-042,8.3086259765625,1.20089340209961,8.34635546875,1.19539332389832,8.33312280273438,1.19739329814911,,,4.28744293253627e-005,3.3623782620678e-005,3.25821036734852e-005,,4,8308.6259765625,8346.35546875,8333.12280273438,
,20124304.843,,15.7399518489838,100000.666015625,3.58732406867153e-042,8.29915698242188,1.20089340209961,8.3368173828125,1.19539332389832,8.32360864257813,1.19739329814911,,,5.26003476189176e-005,4.61729449578867e-005,4.3669667497718e-005,,4,8299.15698242188,8336.8173828125,8323.60864257813,
,20124474.328,,15.1735394001007,100000.41015625,3.58732406867153e-042,8.28590063476562,1.20089340209961,8.3234677734375,1.19539332389832,8.31029663085937,1.19739329814911,,,7.91569430897722e-005,7.11451786371737e-005,6.44138436300577e-005,,4,8285.90063476563,8323.4677734375,8310.29663085938,
,20124644.468,,14.6075098514557,100000.38671875,3.58732406867153e-042,8.26704638671875,1.20089340209961,8.30450122070313,1.19539332389832,8.29151806640625,1.19739329814911,,,0.000114974501555984,0.000104873351965869,9.30569582757199e-005,,4,8267.04638671875,8304.50122070313,8291.51806640625,
,20124814.562,,14.0423181056976,100000.57421875,3.58732406867153e-042,8.2392060546875,1.20089340209961,8.2764755859375,1.19539332389832,8.2634814453125,1.19739329814911,,,0.00017041363007715,0.000173635972470636,0.000160648262642559,,4,8239.2060546875,8276.4755859375,8263.4814453125,
,20124982.5,,13.4808051586151,100000.509765625,3.58732406867153e-042,8.1951904296875,1.20089340209961,8.23213330078125,1.19539332389832,8.21934692382812,1.19739329814911,,,0.000250201158668408,0.000232496258467185,0.000243867390861505,,4,8195.1904296875,8232.13330078125,8219.34692382813,
,20125152.546,,12.9149920940399,100000.59765625,3.58732406867153e-042,8.11278637695312,1.20089340209961,8.14903564453125,1.19539332389832,8.13708483886719,1.19739329814911,,,0.000492063068314486,0.000520618550011054,0.000494595793924868,,4,8112.78637695313,8149.03564453125,8137.08483886719,
,20125320.859,,12.3530337810516,100000.283203125,3.58732406867153e-042,7.89844116210937,1.20089340209961,7.93235583496094,1.19539332389832,7.92085510253906,1.19739329814911,,,0.00213628416547386,0.00211331324416704,0.00206880952115187,,4,7898.44116210938,7932.35583496094,7920.85510253906,
,20125490.046,,11.7898218631744,100000.404296875,3.58732406867153e-042,6.50932238769531,1.51914823055267,6.52009997558594,1.51139807701111,6.54067883300781,1.51789820194244,,,0.0541527085611251,0.0584464018945596,0.047608306571585,,4,6509.32238769531,6520.09997558594,6540.67883300781,
,20125660.937,,11.2205543518066,100000.47265625,3.58732406867153e-042,1.10297744750977,8.73263359069824,1.11899816894531,8.76638412475586,1.11142175292969,8.66638231277466,,,0.0178591367163229,0.0191459099575287,0.0191865484853363,,4,1102.97744750977,1118.99816894531,1111.42175292969,
,20125829.234,,10.6591808795929,100000.564453125,3.58732406867153e-042,0.0209426975250244,9.85140037536621,0.0232993626594543,9.55389595031738,0.0201022691726685,9.77389907836914,,,0.000506620975623222,0.000525430628435622,0.000519939838218597,,4,20.9426975250244,23.2993626594543,20.1022691726685,
,20125996.062,,10.1130342483521,100000.59375,3.58732406867153e-042,0.000115542972460389,9.85140037536621,0.000153223603963852,9.55389595031738,9.52688716351986e-005,9.77389907836914,,,4.14937647415312e-006,6.12148051809572e-006,4.09617862266206e-006,,4,0.115542972460389,0.153223603963852,0.0952688716351986,
,20126159.093,,9.53348660469055,100000.708984375,3.58732406867153e-042,-2.11999373277649e-007,9.85140037536621,1.24902298193774e-006,9.55389595031738,2.28926262934692e-007,9.77389907836914,,,2.32438277483035e-006,1.12823512177012e-006,1.24555593884361e-006,,4,-0.000211999373277649,0.00124902298193774,0.000228926262934692,
,20126310.093,,8.93250894546509,100000.484375,3.58732406867153e-042,7.04064834280871e-007,9.85140037536621,3.59095341991633e-007,9.55389595031738,-2.44124501477927e-007,9.77389907836914,,,1.19014413677011e-006,1.350402433115e-006,5.34357989609617e-007,,4,0.000704064834280871,0.000359095341991633,-0.000244124501477927,
,20126466.062,,8.40635871887207,100000.556640625,3.58732406867153e-042,1.43838144140318e-007,9.85140037536621,-8.97726145922206e-007,9.55389595031738,1.60248404426966e-007,9.77389907836914,,,5.24682214040875e-007,6.13662983943901e-007,9.65532752538987e-007,,4,0.000143838144140318,-0.000897726145922206,0.000160248404426966,
,20126635.703,,7.84388029575348,100000.63671875,3.58732406867153e-042,9.08501533558593e-008,9.85140037536621,-1.71761363162659e-007,9.55389595031738,-2.82334476651158e-007,9.77389907836914,,,9.73067261109289e-007,1.52482463335553e-006,6.61130129339971e-007,,4,9.08501533558592e-005,-0.000171761363162659,-0.000282334476651158,
,20126805.437,,7.27399361133575,100000.65625,3.58732406867153e-042,1.07500467493082e-006,9.85140037536621,8.58806888572872e-008,9.55389595031738,-3.12850042973878e-007,9.77389907836914,,,7.81636185260404e-007,1.0876059609876e-006,5.58418386426583e-007,,4,0.00107500467493082,8.58806888572872e-005,-0.000312850042973878,
,20126974.593,,6.71279191970825,100000.21484375,3.58732406867153e-042,-9.38753102673218e-007,9.85140037536621,9.28944373299601e-007,9.55389595031738,-9.7671242110664e-007,9.77389907836914,,,1.71974263678021e-006,6.19145168454928e-007,1.00329072918545e-006,,4,-0.000938753102673218,0.000928944373299601,-0.00097671242110664,
,20127143.453,,6.14981913566589,100000.2578125,3.58732406867153e-042,-1.05999642983079e-007,9.85140037536621,1.09276123112068e-007,9.55389595031738,-1.12169112253468e-006,9.77389907836914,,,1.82707494427148e-006,1.30222955512255e-006,1.35584200492332e-006,,4,-0.000105999642983079,0.000109276123112068,-0.00112169112253468,
,20127311.656,,5.58675849437714,100000.41796875,3.58732406867153e-042,-1.55196781270206e-006,9.85140037536621,1.09276108560152e-007,9.55389595031738,-9.53795970417559e-007,9.77389907836914,,,1.62771616467396e-006,1.00079335370871e-006,1.26351695486317e-006,,4,-0.00155196781270206,0.000109276108560152,-0.000953795970417559,
,20127482.718,,5.02004265785217,100000.46484375,3.58732406867153e-042,5.22364574862877e-007,9.85140037536621,-6.24487114691874e-007,9.55389595031738,-5.64668938750401e-007,9.77389907836914,,,6.28466957546354e-007,1.63136477121078e-006,1.03249117064012e-006,,4,0.000522364574862877,-0.000624487114691874,-0.000564668938750401,
,20127651.109,,4.45848512649536,100000.4453125,3.58732406867153e-042,-5.82915592531208e-007,9.85140037536621,-7.41610449040309e-007,9.55389595031738,-1.04541409382364e-006,9.77389907836914,,,1.08963996532721e-006,7.5988124163869e-007,8.88912601595331e-007,,4,-0.000582915592531208,-0.000741610449040309,-0.00104541409382364,
,20127820.093,,3.89523136615753,100000.51953125,3.58732406867153e-042,-3.48250927345362e-007,9.85140037536621,1.32695895445067e-007,9.55389595031738,-1.22109864605591e-007,9.77389907836914,,,1.08561712496847e-006,3.33686345153195e-007,1.2571732075713e-006,,4,-0.000348250927345362,0.000132695895445067,-0.000122109864605591,
,20127989.39,,3.33068424463272,100000.58203125,3.58732406867153e-042,-4.54250834991399e-008,9.85140037536621,4.44951641838998e-007,9.55389595031738,-1.38875590710086e-006,9.77389907836914,,,1.10322185242839e-006,1.45532757644846e-006,1.11090902403428e-006,,4,-4.54250834991399e-005,0.000444951641838998,-0.00138875590710086,
,20128084.671,,3.0139986872673,100000.587890625,3.58732406867153e-042,2.27078035095474e-007,9.85140037536621,-4.44951641838998e-007,9.55389595031738,-1.90787763131084e-007,9.77389907836914,,,8.46132015334092e-007,2.38321694182484e-006,9.41812280706506e-007,,4,0.000227078035095474,-0.000444951641838998,-0.000190787763131084,