File: unit_testing/Test sets/S806_52_2.dat
[Header]
TITLE, S806-52
FILEOPENTIME,1715870273.00,5/16/2024,10:37 AM
BYAPP, Resistivity, 2.0, 1.0
INFO, Test structure CG, Sample1 Name
INFO, 1, Sample1 Cross Section
INFO, 1, Sample1 Length
INFO, Ohm, Sample1 Units
INFO, Line 2, Sample2 Name
INFO, 1, Sample2 Cross Section
INFO, 1, Sample2 Length
INFO, Ohm, Sample2 Units
INFO, Test structure CD, Sample3 Name
INFO, 1, Sample3 Cross Section
INFO, 1, Sample3 Length
INFO, Ohm, Sample3 Units
INFO, , Sample4 Name
INFO, 1, Sample4 Cross Section
INFO, 1, Sample4 Length
INFO, Ohm-m, Sample4 Units
FIELDGROUP, Resistivity,2,3,4,5,6,7,8,9,10,11,12,13,14,15,16,17,18,19,20,21,22,23,24,25,26,27,28,29,30,31,32,33,34,35,36,37,38,39,40,41
STARTUPGROUP, Resistivity
STARTUPAXIS, X, 2, LINEAR, AUTO
STARTUPAXIS, Y1, 7, LINEAR, AUTO
STARTUPAXIS, Y2, 9, LINEAR, AUTO
STARTUPAXIS, Y3, 11, LINEAR, AUTO
PLOT_APPEARANCE, ALL, HORZ_GRID_ON, VERT_GRID_ON, MARKERS_AND_LINES, ALL_LINES
DATATYPE, TIME, 2
DATATYPE, COMMENT, 1
[Data]
Comment,Time Stamp (sec),Status (code),Temperature (K),Magnetic Field (Oe),Sample Position (degrees),Bridge 1 Resistivity (Ohm),Bridge 1 Excitation (uA),Bridge 2 Resistivity (Ohm),Bridge 2 Excitation (uA),Bridge 3 Resistivity (Ohm),Bridge 3 Excitation (uA),Bridge 4 Resistivity (Ohm-m),Bridge 4 Excitation (uA),Bridge 1 Std. Dev. (Ohm),Bridge 2 Std. Dev. (Ohm),Bridge 3 Std. Dev. (Ohm),Bridge 4 Std. Dev. (Ohm-m),Number of Readings,Bridge 1 Resistance (Ohms),Bridge 2 Resistance (Ohms),Bridge 3 Resistance (Ohms),Bridge 4 Resistance (Ohms)
,11877718.5,,299.999774169922,0.151487378776073,90.0002899169922,142.306210327148,0.999890267848969,1411.47502441406,0.999890267848969,137.666201782227,0.999890267848969,,,0.0147096447914783,0.0347195597379511,0.00806444798564597,,5,142.306210327148,1411.47502441406,137.666201782227,
,11878629.61,,226.778698730469,0.114539235830307,90.0002899169922,116.811744689941,0.999890267848969,1201.44768066406,0.999890267848969,112.742626953125,0.999890267848969,,,0.0347405282125723,0.34605352510265,0.0398805742708162,,5,116.811744689941,1201.44768066406,112.742626953125,
,11879506.735,,153.805053710938,0.177351078391075,90.0002899169922,87.3540145874023,0.999890267848969,899.712878417969,0.999890267848969,84.2695541381836,0.999890267848969,,,0.0347012831777782,0.369611501126463,0.0434477257656482,,5,87.3540145874023,899.712878417969,84.2695541381836,
,11880383.844,,80.8656326293945,0.173656263947487,90.0002899169922,53.9879669189453,0.999890267848969,557.61513671875,0.999890267848969,52.0526969909668,0.999890267848969,,,0.0269316484246923,0.41211777916922,0.0386749215729182,,5,53.9879669189453,557.61513671875,52.0526969909668,
,11884732.235,,11.0009328842163,0.147792559862137,90.0002899169922,32.1983345031738,0.999890267848969,333.920257568359,0.999890267848969,31.0028720855713,0.999890267848969,,,0.00737692994930733,0.00233350678569374,0.0197554735751056,,5,32.1983345031738,333.920257568359,31.0028720855713,
,11884922.719,,10.3668687820435,0.0849807225167751,90.0002899169922,32.1807319641113,0.999890267848969,333.741461181641,0.999890267848969,30.9848518371582,0.999890267848969,,,0.0191978100543186,0.00927090499829358,0.00759950754081086,,5,32.1807319641113,333.741461181641,30.9848518371582,
,11885113.25,,9.74180889129639,0.0923703521490097,90.0002899169922,32.1688568115234,0.999890267848969,333.597308349609,0.999890267848969,30.9769157409668,0.999890267848969,,,0.0117100157414585,0.0110411000543349,0.0175767139443917,,5,32.1688568115234,333.597308349609,30.9769157409668,
,11885292.344,,9.11369094848633,0.103454792499542,90.0002899169922,32.1211212158203,0.999890267848969,333.276568603516,0.999890267848969,30.9427242279053,0.999890267848969,,,0.0125639854663159,0.0193454164392776,0.00880389319954251,,5,32.1211212158203,333.276568603516,30.9427242279053,
,11885487.985,,8.49256839752197,0.0923703499138355,90.0002899169922,-0.00483353580348194,0.999890267848969,-0.0112780639203265,0.999890267848969,0.0171255484223366,0.999890267848969,,,0.0100282673130296,0.00598043994787053,0.00978616871200763,,5,-0.00483353580348194,-0.0112780639203265,0.0171255484223366,
,11885677.188,,7.8678409576416,0.0775910943746567,90.0002899169922,0.000477261864580214,0.999890267848969,-0.00358021068386734,0.999890267848969,-0.00626513608731329,0.999890267848969,,,0.0107087605852912,0.00943521772239854,0.0112731615393701,,5,0.000477261864580214,-0.00358021068386734,-0.00626513608731329,
,11885863.328,,7.24173135757446,0.0923703528940678,90.0002899169922,-0.00727982996031642,0.999890267848969,0.00435608746483922,0.999890267848969,-0.00352059944998473,0.999890267848969,,,0.0113462096352157,0.0112263802425269,0.00872977333918476,,5,-0.00727982996031642,0.00435608746483922,-0.00352059944998473,
,11886050.391,,6.61864957809448,0.114539235830307,90.0002899169922,0.00668315915390849,0.999890267848969,0.0131874844431877,0.999890267848969,0.0051913891453296,0.999890267848969,,,0.00875093278758548,0.00507889001870897,0.0118827966281208,,5,0.00668315915390849,0.0131874844431877,0.0051913891453296,
,11886238.203,,5.99309110641479,0.129318492114544,90.0002899169922,0.00119352764450014,0.999890267848969,0.00745903600472957,0.999890267848969,-0.00572826233692467,0.999890267848969,,,0.00999249437149333,0.00523987803379452,0.0078880754821659,,5,0.00119352764450014,0.00745903600472957,-0.00572826233692467,
,11886425.781,,5.36822671890259,0.125623679161072,90.0002899169922,0.00161117860116065,0.999890267848969,0.0052510003792122,0.999890267848969,0.0052511865273118,0.999890267848969,,,0.00631671818235142,0.00656576541089274,0.0064339185595868,,5,0.00161117860116065,0.0052510003792122,0.0052511865273118,
,11886613.875,,4.74100408554077,0.144097749888897,90.0002899169922,-0.00912945326417685,0.999890267848969,-0.00322217093780637,0.999890267848969,-0.00907021453604102,0.999890267848969,,,0.0140952962721367,0.00915790588198365,0.0142759061985738,,5,-0.00912945326417685,-0.00322217093780637,-0.00907021453604102,
,11886801.469,,4.11630601882935,0.0886755391955376,90.0002899169922,-0.0106812069192529,0.999890267848969,0.0020288294646889,0.999890267848969,-0.000656095589511097,0.999890267848969,,,0.014678874827923,0.0117802975813153,0.0102340314423897,,5,-0.0106812069192529,0.0020288294646889,-0.000656095589511097,
,11886988.985,,3.49128565788269,0.125623677670956,90.0002899169922,0.000596484681591392,0.999890267848969,0.00560904007870704,0.999890267848969,-0.00220766318961978,0.999890267848969,,,0.0135785158217362,0.00782468902942747,0.0144764485056474,,5,0.000596484681591392,0.00560904007870704,-0.00220766318961978,
,11887176.219,,2.86801519393921,0.133013305068016,90.0002899169922,-0.00680256765335798,0.999890267848969,-0.00381884169764817,0.999890267848969,0.0112180800409988,0.999890267848969,,,0.00842935349233951,0.012400570777793,0.0074473101268139,,5,-0.00680256765335798,-0.00381884169764817,0.0112180800409988,
,11887363.688,,2.24265565872192,0.103454792499542,90.0002899169922,-0.00226746054831892,0.999890267848969,0.00596707966178656,0.999890267848969,0.00173058696091175,0.999890267848969,,,0.00457788812451538,0.0113469171316238,0.0172093188441144,,5,-0.00226746054831892,0.00596707966178656,0.00173058696091175,
,11887963.813,,10.6166044235229,2000.4572265625,90.0002899169922,32.1909957885742,0.999890267848969,333.815124511719,0.999890267848969,30.9997104644775,0.999890267848969,,,0.00513430849027097,0.0140115637680601,0.0150367840898437,,5,32.1909957885742,333.815124511719,30.9997104644775,
,11888151.375,,9.99184818267822,2000.39819335938,90.0002899169922,32.1714233398437,0.999890267848969,333.676928710937,0.999890267848969,30.9819286346436,0.999890267848969,,,0.0128360849379206,0.0144168684741315,0.00922242923016217,,5,32.1714233398437,333.676928710937,30.9819286346436,
,11888339.469,,9.36469573974609,2000.42407226563,90.0002899169922,32.1597267150879,0.999890267848969,333.494354248047,0.999890267848969,30.9664134979248,0.999890267848969,,,0.00746373399483825,0.0200783215952175,0.0134256217660129,,5,32.1597267150879,333.494354248047,30.9664134979248,
,11888526.422,,8.74107246398926,2000.42036132813,90.0002899169922,32.1418853759766,0.999890267848969,333.344219970703,0.999890267848969,30.9544784545898,0.999890267848969,,,0.0137443419813625,0.0219067462529795,0.0148151409356813,,5,32.1418853759766,333.344219970703,30.9544784545898,
,11888713.938,,8.1172119140625,2000.36494140625,90.0002899169922,0.0183190759737045,0.999890267848969,0.107587945461273,0.999890267848969,0.0222573265433311,0.999890267848969,,,0.0106047631393847,0.00765682116323603,0.0117304522207583,,5,0.0183190759737045,0.107587945461273,0.0222573265433311,
,11888901.656,,7.49245586395264,2000.36494140625,90.0002899169922,-0.0116361035965383,0.999890267848969,0.00865256367251277,0.999890267848969,0.00184980966150761,0.999890267848969,,,0.00517126238996788,0.0135179894266429,0.0140733136304477,,5,-0.0116361035965383,0.00865256367251277,0.00184980966150761,
,11889088.656,,6.86846952438354,2000.36491699219,90.0002899169922,0.00381902791559696,0.999890267848969,0.000178833585232496,0.999890267848969,-0.000417650816962123,0.999890267848969,,,0.0140746203657003,0.0182048441121475,0.00389726409229497,,5,0.00381902791559696,0.000178833585232496,-0.000417650816962123,
,11889277.016,,6.24117908477783,2000.3353515625,90.0002899169922,-0.000954710505902767,0.999890267848969,-0.00220747669227421,0.999890267848969,-0.0079362979857251,0.999890267848969,,,0.0170200169227562,0.00727050657640625,0.00862783040946292,,5,-0.000954710505902767,-0.00220747669227421,-0.0079362979857251,
,11889464.61,,5.6161036491394,2000.36125488281,90.0002899169922,-0.00256551641505212,0.999890267848969,0.00184980963822454,0.999890267848969,-0.00184999583289027,0.999890267848969,,,0.00640375816964914,0.00950879465594877,0.0185736054166132,,5,-0.00256551641505212,0.00184980963822454,-0.00184999583289027,
,11889651.266,,4.99355659484863,2000.37233886719,90.0002899169922,-0.00471394103951752,0.999890267848969,-0.00525081411469728,0.999890267848969,-0.00805552019737661,0.999890267848969,,,0.00661632513254203,0.00838929789294555,0.00704533885686956,,5,-0.00471394103951752,-0.00525081411469728,-0.00805552019737661,
,11889839.016,,4.36818990707397,2000.42770996094,90.0002899169922,0.00441588470130228,0.999890267848969,-0.00208844065782614,0.999890267848969,-0.000417651049792767,0.999890267848969,,,0.00836968581659466,0.00806786948375886,0.0182682126014638,,5,0.00441588470130228,-0.00208844065782614,-0.000417651049792767,
,11890026.938,,3.74194250106812,2000.41665039062,90.0002899169922,0.00907021472230554,0.999890267848969,0.00190942087210715,0.999890267848969,-0.0026852976065129,0.999890267848969,,,0.013003318140902,0.0140457606381122,0.00466814729411271,,5,0.00907021472230554,0.00190942087210715,-0.0026852976065129,
,11890214.156,,3.11719417572021,2000.40930175781,90.0002899169922,-0.000954710226505995,0.999890267848969,0.000596857257187366,0.999890267848969,0.00262568648904562,0.999890267848969,,,0.0159118235641798,0.017605810631273,0.00630210690080957,,5,-0.000954710226505995,0.000596857257187366,0.00262568648904562,
,11890401.797,,2.49123554229736,2000.41662597656,90.0002899169922,0.00531079752836376,0.999890267848969,0.00322217093780637,0.999890267848969,-0.00262550024781376,0.999890267848969,,,0.0175049907462301,0.0154515648704342,0.00766364878288403,,5,0.00531079752836376,0.00322217093780637,-0.00262550024781376,
,11891004.344,,10.8691017150879,4000.29760742188,90.0002899169922,32.1965454101562,0.999890267848969,333.870166015625,0.999890267848969,31.0051998138428,0.999890267848969,,,0.01779811010139,0.0205155369425509,0.0119731717431307,,5,32.1965454101562,333.870166015625,31.0051998138428,
,11891192.281,,10.2423833847046,4000.32709960938,90.0002899169922,32.1789421081543,0.999890267848969,333.751922607422,0.999890267848969,30.9767360687256,0.999890267848969,,,0.00568847094338445,0.0144017493088388,0.0216373216583269,,5,32.1789421081543,333.751922607422,30.9767360687256,
,11891379.61,,9.61740550994873,4000.2458984375,90.0002899169922,32.1764953613281,0.999890267848969,333.579742431641,0.999890267848969,30.9721420288086,0.999890267848969,,,0.0163396618647106,0.0161755601836565,0.0119567754234816,,5,32.1764953613281,333.579742431641,30.9721420288086,
,11891567.375,,8.9920768737793,4000.29755859375,90.0002899169922,32.1621139526367,0.999890267848969,333.479962158203,0.999890267848969,30.9603862762451,0.999890267848969,,,0.0148348163864999,0.0232979799051152,0.0152582100743477,,5,32.1621139526367,333.479962158203,30.9603862762451,
,11891754.672,,8.36886940002441,4000.2791015625,90.0002899169922,32.1442123413086,0.999890267848969,333.319464111328,0.999890267848969,30.9605052947998,0.999890267848969,,,0.0120111081488001,0.00879402897835751,0.00926835184155266,,5,32.1442123413086,333.319464111328,30.9605052947998,
,11891942.953,,7.74093542098999,4000.26430664062,90.0002899169922,32.1045310974121,0.999890267848969,333.029040527344,0.999890267848969,30.9031616210938,0.999890267848969,,,0.0194054893077605,0.0254662532502258,0.00373840669588014,,5,32.1045310974121,333.029040527344,30.9031616210938,
,11892129.813,,7.11937246322632,4000.29028320313,90.0002899169922,-0.00131293656304479,0.999890267848969,-0.00507198057603091,0.999890267848969,-0.0076380557846278,0.999890267848969,,,0.0155483275369332,0.0102940845602598,0.0153271511957647,,5,-0.00131293656304479,-0.00507198057603091,-0.0076380557846278,
,11892318.016,,6.49125967025757,4000.29384765625,90.0002899169922,0.00298353985417634,0.999890267848969,-0.00375923048704863,0.999890267848969,0.00238724171649665,0.999890267848969,,,0.00929782699306326,0.0122736694856396,0.00469477357146442,,5,0.00298353985417634,-0.00375923048704863,0.00238724171649665,
,11892505.047,,5.86822156906128,4000.26430664062,90.0002899169922,0.00531042525544763,0.999890267848969,0.00369961922988296,0.999890267848969,0.00322217070497572,0.999890267848969,,,0.00990339490841962,0.0118453342938358,0.0116604490232867,,5,0.00531042525544763,0.00369961922988296,0.00322217070497572,
,11892692.625,,5.24296283721924,4000.32333984375,90.0002899169922,-0.000954337842995301,0.999890267848969,-0.0044158848002553,0.999890267848969,0.00101450784131885,0.999890267848969,,,0.0136532393344624,0.0100429867753856,0.00739217095596786,,5,-0.000954337842995301,-0.0044158848002553,0.00101450784131885,
,11892880.078,,4.61792593002319,4000.27172851563,90.0002899169922,-0.0039978614076972,0.999890267848969,-0.00173058729851618,0.999890267848969,0.00543039264157414,0.999890267848969,,,0.0175668401110378,0.0128060062795881,0.0175068112531838,,5,-0.0039978614076972,-0.00173058729851618,0.00543039264157414,
,11893067.891,,3.99252109527588,4000.26806640625,90.0002899169922,0.00274509487207979,0.999890267848969,0.00226708806585521,0.999890267848969,-0.00608630212955177,0.999890267848969,,,0.00906214717973839,0.00768753657190416,0.00911156388720118,,5,0.00274509487207979,0.00226708806585521,-0.00608630212955177,
,11893255.563,,3.36636080741882,4000.26806640625,90.0002899169922,-0.00960690192878246,0.999890267848969,0.006205710535869,0.999890267848969,-0.00155156720429659,0.999890267848969,,,0.0184013426684346,0.0113147355686751,0.0115851600841456,,5,-0.00960690192878246,0.006205710535869,-0.00155156720429659,
,11893442.485,,2.74387497901917,4000.31977539063,90.0002899169922,0.0108602266293019,0.999890267848969,-0.00459509105421603,0.999890267848969,-0.0098460913868621,0.999890267848969,,,0.0137871008097523,0.00438723966774448,0.0212862943676122,,5,0.0108602266293019,-0.00459509105421603,-0.0098460913868621,
,11893630.985,,2.1155800819397,4000.29018554687,90.0002899169922,-0.00340119078755379,0.999890267848969,0.00387845271034166,0.999890267848969,-0.00250627771019936,0.999890267848969,,,0.0124918472506894,0.00521214772707914,0.0123096006810605,,5,-0.00340119078755379,0.00387845271034166,-0.00250627771019936,
,11894231.235,,10.4930685043335,6000.06396484375,90.0002899169922,32.1868782043457,0.999890267848969,333.816339111328,0.999890267848969,30.9974418640137,0.999890267848969,,,0.00918191308571105,0.0169276291750815,0.0135802677967487,,5,32.1868782043457,333.816339111328,30.9974418640137,
,11894418.297,,9.86939926147461,6000.11220703125,90.0002899169922,32.1812088012695,0.999890267848969,333.676818847656,0.999890267848969,30.9868804931641,0.999890267848969,,,0.0132782746831093,0.0103877995954606,0.0141696983887915,,5,32.1812088012695,333.676818847656,30.9868804931641,
,11894606.594,,9.24169616699219,6000.1306640625,90.0002899169922,32.1640251159668,0.999890267848969,333.540319824219,0.999890267848969,30.9724403381348,0.999890267848969,,,0.00413249761529939,0.0121900428337616,0.0108502821397839,,5,32.1640251159668,333.540319824219,30.9724403381348,
,11894794.563,,8.61576614379883,6000.07880859375,90.0002899169922,32.1558486938477,0.999890267848969,333.426330566406,0.999890267848969,30.9661739349365,0.999890267848969,,,0.00906118503125353,0.024262929368939,0.00928220579342485,,5,32.1558486938477,333.426330566406,30.9661739349365,
,11894981.953,,7.99043064117432,6000.16728515625,90.0002899169922,32.1502990722656,0.999890267848969,333.328662109375,0.999890267848969,30.9488700866699,0.999890267848969,,,0.00749711839079685,0.00783006641512428,0.0237865053094842,,5,32.1502990722656,333.328662109375,30.9488700866699,
,11895168.703,,7.36809368133545,6000.14541015625,90.0002899169922,32.1267295837402,0.999890267848969,333.210638427734,0.999890267848969,30.9495265960693,0.999890267848969,,,0.0099611580913529,0.00529078157964457,0.0197425613026999,,5,32.1267295837402,333.210638427734,30.9495265960693,
,11895356.219,,6.74374704360962,6000.09736328125,90.0002899169922,0.00739923864603043,0.999890267848969,0.0990549772977829,0.999890267848969,0.00340137698221952,0.999890267848969,,,0.0123210643606599,0.0148004627831657,0.00664647857588509,,5,0.00739923864603043,0.0990549772977829,0.00340137698221952,
,11895544.047,,6.11788520812988,6000.16376953125,90.0002899169922,0.00238724178634584,0.999890267848969,-0.00739923855289817,0.999890267848969,0.00751864677295089,0.999890267848969,,,0.0103575715985768,0.0146158640753446,0.0186759782643827,,5,0.00238724178634584,-0.00739923855289817,0.00751864677295089,
,11895731.219,,5.49354248046875,6000.15634765625,90.0002899169922,0.00477392475586385,0.999890267848969,-0.00286431764252484,0.999890267848969,0.0022670878097415,0.999890267848969,,,0.00787586081802307,0.0162964848646607,0.0103635684986732,,5,0.00477392475586385,-0.00286431764252484,0.0022670878097415,
,11895919.047,,4.86863327026367,6000.167578125,90.0002899169922,0.00572844822891057,0.999890267848969,-0.00196921834722161,0.999890267848969,-0.00155156720429659,0.999890267848969,,,0.0161218374023478,0.00807799621242083,0.0112891673137571,,5,0.00572844822891057,-0.00196921834722161,-0.00155156720429659,
,11896107.703,,4.23906621932983,6000.10478515625,90.0002899169922,-0.0142021786421537,0.999890267848969,5.97974751144648e-005,0.999890267848969,0.00280470624566078,0.999890267848969,,,0.00982082723441616,0.0126166199866355,0.00957855997321117,,5,-0.0142021786421537,5.97974751144648e-005,0.00280470624566078,
,11896294.203,,3.61776814460754,6000.14150390625,90.0002899169922,0.00328196831978858,0.999890267848969,0.000298242294229567,0.999890267848969,-0.00572826244169846,0.999890267848969,,,0.00663671075442204,0.00581310632918906,0.00760997956491811,,5,0.00328196831978858,0.000298242294229567,-0.00572826244169846,
,11896481.813,,2.99170255661011,6000.16748046875,90.0002899169922,0.00232707178220153,0.999890267848969,0.00948786532972008,0.999890267848969,-0.00173040088266134,0.999890267848969,,,0.0144271667721087,0.0145525195558255,0.0134432331553173,,5,0.00232707178220153,0.00948786532972008,-0.00173040088266134,
,11896668.891,,2.36851267814636,6000.1931640625,90.0002899169922,-0.00274472256423906,0.999890267848969,0.0109200242906809,0.999890267848969,0.00757844453910366,0.999890267848969,,,0.0114260550716216,0.00635600683686265,0.00828236783679618,,5,-0.00274472256423906,0.0109200242906809,0.00757844453910366,
,11897270.75,,10.7414884567261,8000.2,90.0002899169922,32.1950523376465,0.999890267848969,333.890966796875,0.999890267848969,31.0061550140381,0.999890267848969,,,0.00973698779951464,0.00869249567426374,0.0102979968764382,,5,32.1950523376465,333.890966796875,31.0061550140381,
,11897458.36,,10.1162675857544,8000.2111328125,90.0002899169922,32.1911743164062,0.999890267848969,333.776440429688,0.999890267848969,30.9927284240723,0.999890267848969,,,0.0161169088510793,0.0189378585481497,0.0102881199010765,,5,32.1911743164062,333.776440429688,30.9927284240723,
,11897645.672,,9.49170703887939,8000.15546875,90.0002899169922,32.1615783691406,0.999890267848969,333.637939453125,0.999890267848969,30.9767959594727,0.999890267848969,,,0.010421591906452,0.0165103539485629,0.0114154071883118,,5,32.1615783691406,333.637939453125,30.9767959594727,
,11897833.328,,8.86696472167969,8000.207421875,90.0002899169922,32.1628295898438,0.999890267848969,333.459973144531,0.999890267848969,30.9590141296387,0.999890267848969,,,0.00947100092720448,0.00750664382270399,0.00543803668298719,,5,32.1628295898438,333.459973144531,30.9590141296387,
,11898020.578,,8.24330787658691,8000.22216796875,90.0002899169922,32.1412292480469,0.999890267848969,333.387438964844,0.999890267848969,30.9564479827881,0.999890267848969,,,0.0127576009587995,0.006516274533826,0.0114123199322409,,5,32.1412292480469,333.387438964844,30.9564479827881,
,11898207.938,,7.61655292510986,8000.23701171875,90.0002899169922,32.1439147949219,0.999890267848969,333.294061279297,0.999890267848969,30.9391437530518,0.999890267848969,,,0.0186028726324492,0.0182442071311556,0.0121869643124371,,5,32.1439147949219,333.294061279297,30.9391437530518,
,11898395.344,,6.99363527297974,8000.2220703125,90.0002899169922,32.1353233337402,0.999890267848969,333.226049804687,0.999890267848969,30.9372337341309,0.999890267848969,,,0.015795555147405,0.00804880964560078,0.0146980352744217,,5,32.1353233337402,333.226049804687,30.9372337341309,
,11898583,,6.36826400756836,8000.2259765625,90.0002899169922,8.42891569137573,0.999890267848969,69.457844543457,0.999890267848969,3.11700744628906,0.999890267848969,,,0.335168718678236,3.42987653665306,0.208223328640238,,5,8.42891569137573,69.457844543457,3.11700744628906,
,11898770.844,,5.74210968017578,8000.11474609375,90.0002899169922,0.00650413925759494,0.999890267848969,0.0170066988095641,0.999890267848969,-0.00387901160866022,0.999890267848969,,,0.00648866971677862,0.0137595341993219,0.00901208186867783,,5,0.00650413925759494,0.0170066988095641,-0.00387901160866022,
,11898958.875,,5.11567010879517,8000.25888671875,90.0002899169922,-0.00572863526176661,0.999890267848969,0.00286431752610952,0.999890267848969,-0.0010145079344511,0.999890267848969,,,0.015324643786461,0.011979844647936,0.0098875394514194,,5,-0.00572863526176661,0.00286431752610952,-0.0010145079344511,
,11899145.438,,4.49357213973999,8000.24453125,90.0002899169922,-0.00155138117261231,0.999890267848969,-0.00262568655889481,0.999890267848969,-0.0084731710376218,0.999890267848969,,,0.0104167422660418,0.0081544695460614,0.00805370038625944,,5,-0.00155138117261231,-0.00262568655889481,-0.0084731710376218,
,11899332.938,,3.86879072189331,8000.07421875,90.0002899169922,0.00149158369749784,0.999890267848969,-0.0139035642670933,0.999890267848969,0.00190942082554102,0.999890267848969,,,0.00593135373845713,0.0115503677887973,0.0155725570748257,,5,0.00149158369749784,-0.0139035642670933,0.00190942082554102,
,11899520.703,,3.24244313240051,8000.2037109375,90.0002899169922,0.00465432980563492,0.999890267848969,-0.000119222421199083,0.999890267848969,0.00399823393672705,0.999890267848969,,,0.0141958541720245,0.0156319300027106,0.00972197952719161,,5,0.00465432980563492,-0.000119222421199083,0.00399823393672705,
,11899708.485,,2.61719617843628,8000.21474609375,90.0002899169922,-0.00877141344826668,0.999890267848969,0.00417706740554422,0.999890267848969,0.00799609581008554,0.999890267848969,,,0.00948493891903219,0.00894869613100338,0.0151174712833602,,5,-0.00877141344826668,0.00417706740554422,0.00799609581008554,
,11900307.719,,10.9992589950562,9999.7552734375,90.0002899169922,32.217130279541,0.999890267848969,333.962097167969,0.999890267848969,31.0088405609131,0.999890267848969,,,0.0161637234764735,0.00837470370218234,0.0122299490034855,,5,32.217130279541,333.962097167969,31.0088405609131,
,11900496.516,,10.3694557189941,9999.7736328125,90.0002899169922,32.1798973083496,0.999890267848969,333.769573974609,0.999890267848969,30.9813911437988,0.999890267848969,,,0.00684184091642379,0.0175133100445731,0.00975121437426055,,5,32.1798973083496,333.769573974609,30.9813911437988,
,11900684.906,,9.74208908081055,9999.7921875,90.0002899169922,32.1649192810059,0.999890267848969,333.600396728516,0.999890267848969,30.983837890625,0.999890267848969,,,0.0175761222707403,0.0110716046663675,0.0125950014830861,,5,32.1649192810059,333.600396728516,30.983837890625,
,11900871.735,,9.11924343109131,9999.78125,90.0002899169922,32.1704086303711,0.999890267848969,333.500256347656,0.999890267848969,30.9630115509033,0.999890267848969,,,0.0102643656772272,0.0104612472022627,0.0125066450314799,,5,32.1704086303711,333.500256347656,30.9630115509033,
,11901059.828,,8.49141139984131,9999.8513671875,90.0002899169922,32.1563850402832,0.999890267848969,333.388531494141,0.999890267848969,30.9618183135986,0.999890267848969,,,0.0183886224986046,0.00993103299185731,0.00881987799963996,,5,32.1563850402832,333.388531494141,30.9618183135986,
,11901246.985,,7.86748542785645,9999.8439453125,90.0002899169922,32.1434364318848,0.999890267848969,333.338983154297,0.999890267848969,30.9437969207764,0.999890267848969,,,0.0113770645570005,0.0194601037190159,0.00430539729296369,,5,32.1434364318848,333.338983154297,30.9437969207764,
,11901434.422,,7.24208602905273,9999.81796875,90.0002899169922,32.1341285705566,0.999890267848969,333.289312744141,0.999890267848969,30.9553146362305,0.999890267848969,,,0.00839973608236954,0.00701780722976961,0.00557108201802087,,5,32.1341285705566,333.289312744141,30.9553146362305,
,11901621.844,,6.61832370758057,9999.869921875,90.0002899169922,32.1238052368164,0.999890267848969,333.175103759766,0.999890267848969,30.9437976837158,0.999890267848969,,,0.0127387428068932,0.0101244494503177,0.00550935747959806,,5,32.1238052368164,333.175103759766,30.9437976837158,
,11901809.766,,5.99214773178101,9999.7884765625,90.0002899169922,27.9346172332764,0.999890267848969,296.186480712891,0.999890267848969,24.8614688873291,0.999890267848969,,,0.193043275828564,1.85300695200535,0.331022829283105,,5,27.9346172332764,296.186480712891,24.8614688873291,
,11901998.172,,5.36416711807251,9999.8142578125,90.0002899169922,0.0171259209513664,0.999890267848969,0.187726804614067,0.999890267848969,0.0282245928421617,0.999890267848969,,,0.0158264210380294,0.010808046630464,0.0127210790623996,,5,0.0171259209513664,0.187726804614067,0.0282245928421617,
,11902185.078,,4.7423246383667,9999.74453125,90.0002899169922,0.00519157549133524,0.999890267848969,0.00381902786903083,0.999890267848969,-0.00304333721287549,0.999890267848969,,,0.00709722021556332,0.00422947240774717,0.01150191744864,,5,0.00519157549133524,0.00381902786903083,-0.00304333721287549,
,11902372.828,,4.11654863357544,9999.7076171875,90.0002899169922,0.00196921835886314,0.999890267848969,-0.00572863519191742,0.999890267848969,-0.000656468153465539,0.999890267848969,,,0.0129207331638919,0.00972001416208959,0.013501744616444,,5,0.00196921835886314,-0.00572863519191742,-0.000656468153465539,
,11902559.938,,3.49286704063416,9999.7224609375,90.0002899169922,0.00710099610150792,0.999890267848969,-0.000417837034910917,0.999890267848969,0.0113972862483934,0.999890267848969,,,0.00726295620584893,0.0149063645787743,0.0185119240430069,,5,0.00710099610150792,-0.000417837034910917,0.0113972862483934,
,11902747.235,,2.86789827346802,9999.799609375,90.0002899169922,-0.00489314701408148,0.999890267848969,0.0065043254988268,0.999890267848969,0.00722040499094874,0.999890267848969,,,0.0109780836271821,0.015443947996028,0.00640882129578511,,5,-0.00489314701408148,0.0065043254988268,0.00722040499094874,
,11902934.625,,2.24351077079773,9999.7150390625,90.0002899169922,-0.00751864705234766,0.999890267848969,0.00495257175061852,0.999890267848969,0.00811531767249107,0.999890267848969,,,0.00744909780450007,0.00980967616385483,0.00992494986504514,,5,-0.00751864705234766,0.00495257175061852,0.00811531767249107,
,11903536.141,,10.6178731918335,12000.161328125,90.0002899169922,32.2014389038086,0.999890267848969,333.873071289063,0.999890267848969,31.0025142669678,0.999890267848969,,,0.0129693551741425,0.019869960535295,0.0119336526011954,,5,32.2014389038086,333.873071289063,31.0025142669678,
,11903723.922,,9.99192066192627,12000.109375,90.0002899169922,32.179955291748,0.999890267848969,333.718347167969,0.999890267848969,30.9813903808594,0.999890267848969,,,0.0112522811193568,0.0102807620007079,0.00957437046391394,,5,32.179955291748,333.718347167969,30.9813903808594,
,11903910.922,,9.36869277954102,12000.0759765625,90.0002899169922,32.1610397338867,0.999890267848969,333.558605957031,0.999890267848969,30.9747074127197,0.999890267848969,,,0.00355930154739149,0.0106489923516984,0.0217730505266469,,5,32.1610397338867,333.558605957031,30.9747074127197,
,11904099.328,,8.74137229919434,12000.0982421875,90.0002899169922,32.1520896911621,0.999890267848969,333.456475830078,0.999890267848969,30.9517936706543,0.999890267848969,,,0.00845279849296208,0.00312088401009729,0.0138159757928628,,5,32.1520896911621,333.456475830078,30.9517936706543,
,11904286.953,,8.11667022705078,12000.1279296875,90.0002899169922,32.1516731262207,0.999890267848969,333.35849609375,0.999890267848969,30.959192276001,0.999890267848969,,,0.0131903148663719,0.0118316210327038,0.00973106856790788,,5,32.1516731262207,333.35849609375,30.959192276001,
,11904473.985,,7.49063940048218,12000.0908203125,90.0002899169922,32.1316825866699,0.999890267848969,333.293505859375,0.999890267848969,30.9412315368652,0.999890267848969,,,0.00352404233068234,0.0102531363277666,0.00911646027131168,,5,32.1316825866699,333.293505859375,30.9412315368652,
,11904661.5,,6.86826972961426,12000.06484375,90.0002899169922,32.1291160583496,0.999890267848969,333.251361083984,0.999890267848969,30.9545383453369,0.999890267848969,,,0.0131160509252256,0.00663642215613305,0.010914537595122,,5,32.1291160583496,333.251361083984,30.9545383453369,
,11904850.156,,6.23937892913818,12000.0724609375,90.0002899169922,32.1303085327148,0.999890267848969,333.191015625,0.999890267848969,30.9279842376709,0.999890267848969,,,0.0123369910749303,0.0146137263389071,0.00528511954380802,,5,32.1303085327148,333.191015625,30.9279842376709,
,11905037.297,,5.61534719467163,12000.101953125,90.0002899169922,31.7715042114258,0.999890267848969,330.765173339844,0.999890267848969,30.5040180206299,0.999890267848969,,,0.0155761984179627,0.141799422108959,0.0282338116388691,,5,31.7715042114258,330.765173339844,30.5040180206299,
,11905223.813,,4.99415092468262,11999.5482421875,90.0002899169922,2.98489413261414,0.999890267848969,26.6691020965576,0.999890267848969,1.22845966815948,0.999890267848969,,,0.118921780004963,0.990622490511301,0.043626304434269,,5,2.98489413261414,26.6691020965576,1.22845966815948,
,11905412.078,,4.3667218208313,11999.5927734375,90.0002899169922,-0.00381884146481752,0.999890267848969,0.0507803488522768,0.999890267848969,0.0160516156814992,0.999890267848969,,,0.0110988528525082,0.0163280954220343,0.00734323769090568,,5,-0.00381884146481752,0.0507803488522768,0.0160516156814992,
,11905599.672,,3.74099812507629,12000.0982421875,90.0002899169922,0.000417278078384697,0.999890267848969,-0.0105025596218184,0.999890267848969,0.00119334142655134,0.999890267848969,,,0.00949813852284609,0.0111991039433166,0.00830508854642654,,5,0.000417278078384697,-0.0105025596218184,0.00119334142655134,
,11905787.11,,3.1158878326416,12000.1205078125,90.0002899169922,-0.00143215868156403,0.999890267848969,-0.00548981754109263,0.999890267848969,0.000835488177835941,0.999890267848969,,,0.0124290171000743,0.00972953389297355,0.0104215146965688,,5,-0.00143215868156403,-0.00548981754109263,0.000835488177835941,
,11905975.36,,2.48895745277405,12000.116796875,90.0002899169922,0.000119408674072474,0.999890267848969,-0.00447549624368548,0.999890267848969,0.00226764675462618,0.999890267848969,,,0.00167322091554988,0.00705284567753455,0.00553576695080278,,5,0.000119408674072474,-0.00447549624368548,0.00226764675462618,
,11906577.328,,10.8645475387573,14000.2791015625,90.0002899169922,32.2133125305176,0.999890267848969,333.928802490234,0.999890267848969,30.9953533172607,0.999890267848969,,,0.0117025423842638,0.0120538946823604,0.0116413249273925,,5,32.2133125305176,333.928802490234,30.9953533172607,
,11906764.094,,10.2428888320923,14000.264453125,90.0002899169922,32.1824638366699,0.999890267848969,333.738385009766,0.999890267848969,30.9912368774414,0.999890267848969,,,0.0125713419559727,0.0128138594098836,0.0136585814203175,,5,32.1824638366699,333.738385009766,30.9912368774414,
,11906951.391,,9.61864528656006,14000.2826171875,90.0002899169922,32.1575202941895,0.999890267848969,333.605883789062,0.999890267848969,30.9886116027832,0.999890267848969,,,0.0120400548120006,0.00588350493192211,0.0141354036980376,,5,32.1575202941895,333.605883789062,30.9886116027832,
,11907138.906,,8.99319763183594,14000.2826171875,90.0002899169922,32.1587738037109,0.999890267848969,333.521051025391,0.999890267848969,30.9605052947998,0.999890267848969,,,0.0148630446640843,0.0234581011145832,0.00869339590883389,,5,32.1587738037109,333.521051025391,30.9605052947998,
,11907326.938,,8.36767158508301,14000.3119140625,90.0002899169922,32.1574005126953,0.999890267848969,333.397296142578,0.999890267848969,30.9568656921387,0.999890267848969,,,0.00952364537126482,0.0128717433437379,0.0148873956460023,,5,32.1574005126953,333.397296142578,30.9568656921387,
,11907515.172,,7.73984375,14000.260546875,90.0002899169922,32.1376495361328,0.999890267848969,333.320947265625,0.999890267848969,30.9497650146484,0.999890267848969,,,0.0138258074412245,0.01361276042115,0.0163603600102995,,5,32.1376495361328,333.320947265625,30.9497650146484,
,11907702.25,,7.11693544387817,14000.2568359375,90.0002899169922,32.1407508850098,0.999890267848969,333.240112304688,0.999890267848969,30.9543590545654,0.999890267848969,,,0.0165373241293356,0.00394005416477584,0.00775130527061755,,5,32.1407508850098,333.240112304688,30.9543590545654,
,11907889.547,,6.49249544143677,14000.2607421875,90.0002899169922,32.134366607666,0.999890267848969,333.180474853516,0.999890267848969,30.9367561340332,0.999890267848969,,,0.0117084628298268,0.0113436487211581,0.0155504605674287,,5,32.134366607666,333.180474853516,30.9367561340332,
,11908077.297,,5.86672010421753,14000.3009765625,90.0002899169922,32.1304290771484,0.999890267848969,333.161535644531,0.999890267848969,30.9397399902344,0.999890267848969,,,0.013162075564009,0.0161655784792153,0.0102137811931686,,5,32.1304290771484,333.161535644531,30.9397399902344,
,11908265.156,,5.24138660430908,14000.2642578125,90.0002899169922,32.0712341308594,0.999890267848969,332.896038818359,0.999890267848969,30.8973724365234,0.999890267848969,,,0.0178594862955592,0.0214630072848746,0.00845293357303435,,5,32.0712341308594,332.896038818359,30.8973724365234,
,11908452.047,,4.61842966079712,14000.2607421875,90.0002899169922,18.033959197998,0.999890267848969,187.152059936523,0.999890267848969,11.9810485839844,0.999890267848969,,,0.175088517021295,2.1003831175271,0.193544240905796,,5,18.033959197998,187.152059936523,11.9810485839844,
,11908640.328,,3.98998413085938,14000.275390625,90.0002899169922,0.21219234764576,0.999890267848969,1.67868206501007,0.999890267848969,0.128651927411556,0.999890267848969,,,0.0235572738628754,0.0441618979507226,0.00872370302231771,,5,0.21219234764576,1.67868206501007,0.128651927411556,
,11908826.813,,3.36852359771729,14000.3189453125,90.0002899169922,0.0158131709322333,0.999890267848969,0.0255990924080834,0.999890267848969,-0.000179019873030484,0.999890267848969,,,0.014051435721921,0.0149745517061845,0.00878132088302923,,5,0.0158131709322333,0.0255990924080834,-0.000179019873030484,
,11909015.297,,2.73953313827515,14000.234765625,90.0002899169922,-0.00262587293982506,0.999890267848969,-0.00411727009341121,0.999890267848969,0.00113391652703285,0.999890267848969,,,0.00929484195522003,0.00994443896940505,0.00782690573637393,,5,-0.00262587293982506,-0.00411727009341121,0.00113391652703285,
,11909201.985,,2.11839637756348,14000.2568359375,90.0002899169922,0.00179001218639314,0.999890267848969,0.00966688530170359,0.999890267848969,-0.0032221712404862,0.999890267848969,,,0.0115279818656633,0.00730513241294173,0.0122950952630446,,5,0.00179001218639314,0.00966688530170359,-0.0032221712404862,
,11909801.469,,10.491805267334,16000.2146484375,90.0002899169922,32.1912933349609,0.999890267848969,333.833459472656,0.999890267848969,30.9994716644287,0.999890267848969,,,0.0168328288864378,0.0168051559944013,0.0169806158240044,,5,32.1912933349609,333.833459472656,30.9994716644287,
,11909988.453,,9.86847591400146,16000.2111328125,90.0002899169922,32.1855056762695,0.999890267848969,333.695404052734,0.999890267848969,30.9759605407715,0.999890267848969,,,0.00836379502188877,0.0106657257394318,0.0205793527435556,,5,32.1855056762695,333.695404052734,30.9759605407715,
,11910176.469,,9.24217548370361,16000.1890625,90.0002899169922,32.1615188598633,0.999890267848969,333.570770263672,0.999890267848969,30.9608638763428,0.999890267848969,,,0.00251775271006927,0.0100817995987018,0.0130863840255891,,5,32.1615188598633,333.570770263672,30.9608638763428,
,11910363.985,,8.61600303649902,16000.218359375,90.0002899169922,32.1668884277344,0.999890267848969,333.446234130859,0.999890267848969,30.9675468444824,0.999890267848969,,,0.00932459886090244,0.00601471799083108,0.0148063518085755,,5,32.1668884277344,333.446234130859,30.9675468444824,
,11910551.844,,7.99055023193359,16000.2998046875,90.0002899169922,32.1375289916992,0.999890267848969,333.347717285156,0.999890267848969,30.9521522521973,0.999890267848969,,,0.015362062314381,0.00690579799179189,0.0063087421362267,,5,32.1375289916992,333.347717285156,30.9521522521973,
,11910739.36,,7.36663436889648,16000.2849609375,90.0002899169922,32.1343078613281,0.999890267848969,333.279235839844,0.999890267848969,30.9498245239258,0.999890267848969,,,0.00638622752669113,0.00627959539354981,0.0128637219027491,,5,32.1343078613281,333.279235839844,30.9498245239258,
,11910926.906,,6.74110336303711,16000.2701171875,90.0002899169922,32.1355606079102,0.999890267848969,333.245452880859,0.999890267848969,30.9373531341553,0.999890267848969,,,0.00851790332123854,0.0138650192954917,0.0112660323046801,,5,32.1355606079102,333.245452880859,30.9373531341553,
,11911114.891,,6.11542520523071,16000.35546875,90.0002899169922,32.1366348266602,0.999890267848969,333.195477294922,0.999890267848969,30.9370552062988,0.999890267848969,,,0.0139749931470804,0.0137704505681157,0.0122325598890232,,5,32.1366348266602,333.195477294922,30.9370552062988,
,11911302.485,,5.48999605178833,16000.24453125,90.0002899169922,32.1133628845215,0.999890267848969,333.1255859375,0.999890267848969,30.9289985656738,0.999890267848969,,,0.0105528351541043,0.0112794463758758,0.0151375603680707,,5,32.1133628845215,333.1255859375,30.9289985656738,
,11911489.813,,4.86581773757935,16000.340625,90.0002899169922,32.1114540100098,0.999890267848969,333.064184570312,0.999890267848969,30.9229724884033,0.999890267848969,,,0.0068436183589948,0.012755112725125,0.00645802600368826,,5,32.1114540100098,333.064184570312,30.9229724884033,
,11911676.094,,4.24457817077637,16000.273828125,90.0002899169922,28.1405445098877,0.999890267848969,299.1302734375,0.999890267848969,25.7535594940186,0.999890267848969,,,0.0792815804000761,0.739371388870576,0.11668004345421,,5,28.1405445098877,299.1302734375,25.7535594940186,
,11911864.25,,3.6166919708252,16000.318359375,90.0002899169922,5.77269296646118,0.999890267848969,54.9847206115723,0.999890267848969,2.72878341674805,0.999890267848969,,,0.122742668706468,0.992411834208961,0.0603023681950903,,5,5.77269296646118,54.9847206115723,2.72878341674805,
,11912051.375,,2.99382219314575,16000.3294921875,90.0002899169922,0.115225814282894,0.999890267848969,0.711941993236542,0.999890267848969,0.0643260590732098,0.999890267848969,,,0.0156874569251916,0.0176011212092378,0.00916815687309606,,5,0.115225814282894,0.711941993236542,0.0643260590732098,
,11912238.875,,2.36880059242249,16000.2923828125,90.0002899169922,-0.00686199257615954,0.999890267848969,0.0395024698227644,0.999890267848969,-0.00340137728489935,0.999890267848969,,,0.00611163069528178,0.0085325772689163,0.00759869449311282,,5,-0.00686199257615954,0.0395024698227644,-0.00340137728489935,
,11912837.969,,10.7435253143311,18000.34296875,90.0002899169922,32.2065711975098,0.999890267848969,333.878497314453,0.999890267848969,31.006095123291,0.999890267848969,,,0.0122685310393807,0.0130003394087027,0.0165061464767962,,5,32.2065711975098,333.878497314453,31.006095123291,
,11913026.281,,10.1161357879639,18000.36171875,90.0002899169922,32.1751815795898,0.999890267848969,333.765863037109,0.999890267848969,30.998755645752,0.999890267848969,,,0.00692020418233784,0.00830464763914395,0.009271134842395,,5,32.1751815795898,333.765863037109,30.998755645752,
,11913213.969,,9.4914234161377,18000.350390625,90.0002899169922,32.1646209716797,0.999890267848969,333.595343017578,0.999890267848969,30.9726787567139,0.999890267848969,,,0.0103551741886096,0.0102119937421024,0.0109234109210991,,5,32.1646209716797,333.595343017578,30.9726787567139,
,11913401.11,,8.86803112030029,18000.3875,90.0002899169922,32.1742858886719,0.999890267848969,333.479516601563,0.999890267848969,30.9622360229492,0.999890267848969,,,0.013850863509766,0.0155187135980781,0.0135894837871417,,5,32.1742858886719,333.479516601563,30.9622360229492,
,11913588.735,,8.24237461090088,18000.39140625,90.0002899169922,32.1550720214844,0.999890267848969,333.385406494141,0.999890267848969,30.9562698364258,0.999890267848969,,,0.0115579116295614,0.00790005752305672,0.0146387587495371,,5,32.1550720214844,333.385406494141,30.9562698364258,
,11913776.172,,7.61757974624634,18000.3765625,90.0002899169922,32.1353210449219,0.999890267848969,333.362548828125,0.999890267848969,30.9559104919434,0.999890267848969,,,0.0139499369287052,0.00720858488355719,0.00944005294646232,,5,32.1353210449219,333.362548828125,30.9559104919434,
,11913964.36,,6.99062356948853,18000.365625,90.0002899169922,32.1335311889648,0.999890267848969,333.271392822266,0.999890267848969,30.9409336090088,0.999890267848969,,,0.0120302673989713,0.00599805074233288,0.0145582704959446,,5,32.1335311889648,333.271392822266,30.9409336090088,
,11914150.938,,6.36862564086914,18000.343359375,90.0002899169922,32.1312049865723,0.999890267848969,333.172589111328,0.999890267848969,30.9347873687744,0.999890267848969,,,0.0103718947698528,0.0103683724308338,0.0097262883160038,,5,32.1312049865723,333.172589111328,30.9347873687744,
,11914338.985,,5.74196729660034,18000.40234375,90.0002899169922,32.1314430236816,0.999890267848969,333.217431640625,0.999890267848969,30.9329975128174,0.999890267848969,,,0.00449371466915941,0.011515141866277,0.00930091211800257,,5,32.1314430236816,333.217431640625,30.9329975128174,
,11914527.047,,5.11543083190918,18000.41328125,90.0002899169922,32.1316825866699,0.999890267848969,333.176843261719,0.999890267848969,30.9382484436035,0.999890267848969,,,0.00439773109245937,0.00370415354517982,0.0160428703588532,,5,32.1316825866699,333.176843261719,30.9382484436035,
,11914714.485,,4.49056777954102,18000.394921875,90.0002899169922,32.1177192687988,0.999890267848969,333.128601074219,0.999890267848969,30.9366367340088,0.999890267848969,,,0.0207355109591855,0.00875638642778738,0.0129584241144457,,5,32.1177192687988,333.128601074219,30.9366367340088,
,11914901.985,,3.86553373336792,18000.394921875,90.0002899169922,31.249137878418,0.999890267848969,327.168548583984,0.999890267848969,29.9426273345947,0.999890267848969,,,0.019303766696337,0.158239541730107,0.0307177675857352,,5,31.249137878418,327.168548583984,29.9426273345947,
,11915088.828,,3.24270014762878,18000.40234375,90.0002899169922,19.6214649200439,0.999890267848969,204.974844360352,0.999890267848969,13.8848722457886,0.999890267848969,,,0.0960184031544401,1.24131509093083,0.12887805830216,,5,19.6214649200439,204.974844360352,13.8848722457886,
,11915276.453,,2.61718726158142,18000.37265625,90.0002899169922,3.39525604248047,0.999890267848969,32.7163436889648,0.999890267848969,1.45610735416412,0.999890267848969,,,0.0413972167698038,0.435866684484541,0.0313530656579266,,5,3.39525604248047,32.7163436889648,1.45610735416412,
,11915876.094,,10.9957927703857,19999.854296875,90.0002899169922,32.2207122802734,0.999890267848969,333.963092041016,0.999890267848969,31.016178894043,0.999890267848969,,,0.00552285361735778,0.0119737009425784,0.0106224550422644,,5,32.2207122802734,333.963092041016,31.016178894043,
,11916062.969,,10.3669540405273,19999.85390625,90.0002899169922,32.1857437133789,0.999890267848969,333.749499511719,0.999890267848969,31.0022758483887,0.999890267848969,,,0.00907253409247405,0.004402392032565,0.016683142762416,,5,32.1857437133789,333.749499511719,31.0022758483887,
,11916250.781,,9.74197063446045,19999.84296875,90.0002899169922,32.158772277832,0.999890267848969,333.646551513672,0.999890267848969,30.9812126159668,0.999890267848969,,,0.0147300108758892,0.00491741999410095,0.0149452433209746,,5,32.158772277832,333.646551513672,30.9812126159668,
,11916438.781,,9.11540031433105,19999.824609375,90.0002899169922,32.1646209716797,0.999890267848969,333.515100097656,0.999890267848969,30.9717239379883,0.999890267848969,,,0.00969927797697336,0.0115104980225613,0.00534829147590594,,5,32.1646209716797,333.515100097656,30.9717239379883,
,11916625.86,,8.49159412384033,19999.835546875,90.0002899169922,32.1436752319336,0.999890267848969,333.429992675781,0.999890267848969,30.9621765136719,0.999890267848969,,,0.0109017821407608,0.00672176936415519,0.0119003634633315,,5,32.1436752319336,333.429992675781,30.9621765136719,
,11916813.485,,7.86741333007812,19999.902734375,90.0002899169922,32.1473754882812,0.999890267848969,333.354248046875,0.999890267848969,30.9544792175293,0.999890267848969,,,0.00985003192894178,0.00864866242578239,0.00863402411328548,,5,32.1473754882812,333.354248046875,30.9544792175293,
,11917000.86,,7.24260711669922,20000.35625,90.0002899169922,32.1307266235352,0.999890267848969,333.260144042969,0.999890267848969,30.9467819213867,0.999890267848969,,,0.0143335925519338,0.0149132953829806,0.0143587032636115,,5,32.1307266235352,333.260144042969,30.9467819213867,
,11917188.141,,6.61862525939941,20000.37109375,90.0002899169922,32.136336517334,0.999890267848969,333.229461669922,0.999890267848969,30.9278064727783,0.999890267848969,,,0.00880038417793858,0.0141944075358868,0.00996899685480949,,5,32.136336517334,333.229461669922,30.9278064727783,
,11917375.61,,5.99352598190308,20000.459765625,90.0002899169922,32.1217163085937,0.999890267848969,333.156567382813,0.999890267848969,30.9452301025391,0.999890267848969,,,0.00636738838893816,0.012598010430606,0.0160394705376866,,5,32.1217163085937,333.156567382813,30.9452301025391,
,11917563.75,,5.36602010726929,20000.397265625,90.0002899169922,32.1258338928223,0.999890267848969,333.166174316406,0.999890267848969,30.9350860595703,0.999890267848969,,,0.011972700594941,0.0037398880326345,0.00683173435477773,,5,32.1258338928223,333.166174316406,30.9350860595703,
,11917751.281,,4.74203109741211,20000.408203125,90.0002899169922,32.1217765808105,0.999890267848969,333.168060302734,0.999890267848969,30.9402179718018,0.999890267848969,,,0.00718619511319943,0.015186118647185,0.00898788990255686,,5,32.1217765808105,333.168060302734,30.9402179718018,
,11917939.391,,4.11413869857788,20000.393359375,90.0002899169922,32.1174194335938,0.999890267848969,333.129125976562,0.999890267848969,30.9264930725098,0.999890267848969,,,0.0092280330251686,0.0114166974573006,0.012652750232092,,5,32.1174194335938,333.129125976562,30.9264930725098,
,11918126.328,,3.49114141464233,20000.46015625,90.0002899169922,31.9485500335693,0.999890267848969,332.079956054688,0.999890267848969,30.7467014312744,0.999890267848969,,,0.00459264276280783,0.0315911801958256,0.00721422841285504,,5,31.9485500335693,332.079956054688,30.7467014312744,
,11918313.719,,2.8664125919342,20000.496875,90.0002899169922,28.0040153503418,0.999890267848969,297.922344970703,0.999890267848969,25.5698909759521,0.999890267848969,,,0.0357599533261882,0.45396085489579,0.0780491258009163,,5,28.0040153503418,297.922344970703,25.5698909759521,
,11918501.656,,2.23928112983704,20000.497265625,90.0002899169922,16.5560138702393,0.999890267848969,167.939541625977,0.999890267848969,10.7762786865234,0.999890267848969,,,0.0632134262849813,0.638583438141033,0.0645070078944086,,5,16.5560138702393,167.939541625977,10.7762786865234,
,11919588.781,,47.3223686218262,0.380565840005875,90.0002899169922,39.0747138977051,0.999890267848969,404.631622314453,0.999890267848969,37.6602577209473,0.999890267848969,,,0.028908296317628,0.283667056143343,0.033212565437007,,5,39.0747138977051,404.631622314453,37.6602577209473,
,11920535.688,,122.563514709473,0.343617707490921,90.0002899169922,72.794792175293,0.999890267848969,750.229614257813,0.999890267848969,70.2064331054687,0.999890267848969,,,0.0453867613589719,0.465327841018352,0.0395851529286536,,5,72.794792175293,750.229614257813,70.2064331054687,
,11921451.172,,197.824810791016,0.26972142457962,90.0002899169922,104.642594909668,0.999890267848969,1077.01328125,0.999890267848969,100.982357788086,0.999890267848969,,,0.0404605744768766,0.343048970560968,0.0355591383394862,,5,104.642594909668,1077.01328125,100.982357788086,
,11922360.922,,273.167742919922,0.280805867910385,90.0002899169922,132.699569702148,0.999890267848969,1348.75524902344,0.999890267848969,128.253955078125,0.999890267848969,,,0.025419023126058,0.21032321636224,0.021929468404956,,5,132.699569702148,1348.75524902344,128.253955078125,
,11922714.188,,300.005108642578,0.273416242003441,90.0002899169922,142.14287109375,0.999890267848969,1407.85983886719,0.999890267848969,137.482794189453,0.999890267848969,,,0.0059973868619584,0.0588404923967829,0.0153558272880251,,5,142.14287109375,1407.85983886719,137.482794189453,