File: unit_testing/Test sets/TempSweepFixedField_outplane.dat
[Header]
TITLE, test_recuit
FILEOPENTIME,1721830675.00,7/24/2024,10:17 AM
BYAPP, Resistivity, 2.0, 1.0
INFO, S740Z, Sample1 Name
INFO, 1, Sample1 Cross Section
INFO, 1, Sample1 Length
INFO, Ohm, Sample1 Units
INFO, S726F_850C_30s_4, Sample2 Name
INFO, 1, Sample2 Cross Section
INFO, 1, Sample2 Length
INFO, Ohm, Sample2 Units
INFO, S726F_850C_5s_1, Sample3 Name
INFO, 1, Sample3 Cross Section
INFO, 1, Sample3 Length
INFO, Ohm, Sample3 Units
INFO, , Sample4 Name
INFO, 1, Sample4 Cross Section
INFO, 1, Sample4 Length
INFO, Ohm-m, Sample4 Units
FIELDGROUP, Resistivity,2,3,4,5,6,7,8,9,10,11,12,13,14,15,16,17,18,19,20,21,22,23,24,25,26,27,28,29,30,31,32,33,34,35,36,37,38,39,40,41
STARTUPGROUP, Resistivity
STARTUPAXIS, X, 2, LINEAR, AUTO
STARTUPAXIS, Y1, 7, LINEAR, AUTO
STARTUPAXIS, Y2, 9, LINEAR, AUTO
STARTUPAXIS, Y3, 11, LINEAR, AUTO
PLOT_APPEARANCE, ALL, HORZ_GRID_ON, VERT_GRID_ON, MARKERS_AND_LINES, ALL_LINES
DATATYPE, TIME, 2
DATATYPE, COMMENT, 1
[Data]
Comment,Time Stamp (sec),Status (code),Temperature (K),Magnetic Field (Oe),Sample Position (degrees),Bridge 1 Resistivity (Ohm),Bridge 1 Excitation (uA),Bridge 2 Resistivity (Ohm),Bridge 2 Excitation (uA),Bridge 3 Resistivity (Ohm),Bridge 3 Excitation (uA),Bridge 4 Resistivity (Ohm-m),Bridge 4 Excitation (uA),Bridge 1 Std. Dev. (Ohm),Bridge 2 Std. Dev. (Ohm),Bridge 3 Std. Dev. (Ohm),Bridge 4 Std. Dev. (Ohm-m),Number of Readings,Bridge 1 Resistance (Ohms),Bridge 2 Resistance (Ohms),Bridge 3 Resistance (Ohms),Bridge 4 Resistance (Ohms)
,17839261.547,,18.0011677742004,0.0969888679683208,0,85.8866920471191,9.99890232086182,1679.77908325195,5.95296621322632,353.710517883301,9.99890232086182,,,0.000690143997539409,0.0660696122099792,0.00120792857244039,,4,85.8866920471191,1679.77908325195,353.710517883301,
,17839411.75,,17.4974665641785,0.106225905939937,0,85.8460540771484,9.99890232086182,1692.75360107422,5.90752780437469,353.902000427246,9.99890232086182,,,0.00144941429338144,0.102062370700836,0.00226749661436296,,4,85.8460540771484,1692.75360107422,353.902000427246,
,17839560.734,,16.9991583824158,0.106225905939937,0,85.7944087982178,9.99890232086182,1705.82077026367,5.86265218257904,354.039207458496,9.99890232086182,,,0.00186415301896903,0.0986061579503352,0.000968993177579256,,4,85.7944087982178,1705.82077026367,354.039207458496,
,17839709.344,,16.5064768791199,0.138555528596044,0,85.7305393218994,9.99890232086182,1718.83609008789,5.81827652454376,354.077072143555,9.99890232086182,,,0.00158001587935807,0.0968776708280879,0.00173474380506929,,4,85.7305393218994,1718.83609008789,354.077072143555,
,17839858.547,,16.00794506073,0.0646592462435365,0,85.6505126953125,9.99890232086182,1732.07775878906,5.77371323108673,353.998016357422,9.99890232086182,,,0.00212681603186924,0.0798686474317129,0.00140148468056702,,4,85.6505126953125,1732.07775878906,353.998016357422,
,17840007.281,,15.5126914978027,0.0969888661056757,0,85.5458126068115,9.99890232086182,1745.46102905273,5.72940003871918,353.712745666504,9.99890232086182,,,0.00161386830601832,0.108721599343876,0.0056185660636989,,4,85.5458126068115,1745.46102905273,353.712745666504,
,17840156.25,,15.0172584056854,0.0184740698896348,0,85.411735534668,9.99890232086182,1758.9665222168,5.68546199798584,353.087013244629,9.99890232086182,,,0.00166300676160716,0.0880379343020635,0.00652496133783504,,4,85.411735534668,1758.9665222168,353.087013244629,
,17840305.063,,14.521151304245,0.0785147966817021,0,85.2301387786865,9.99890232086182,1772.68499755859,5.64121127128601,352.113647460938,9.99890232086182,,,0.00163119573001306,0.0911792716496561,0.00938446540630185,,4,85.2301387786865,1772.68499755859,352.113647460938,
,17840453.969,,14.0249466896057,0.101607384160161,0,84.9918937683105,9.99890232086182,1786.52752685547,5.59752309322357,348.632682800293,9.99890232086182,,,0.00187897366052872,0.0906922658026888,0.0498023517612571,,4,84.9918937683105,1786.52752685547,348.632682800293,
,17840603.328,,13.5269021987915,0.0923703499138355,0,84.6459197998047,9.99890232086182,1800.68435668945,5.5534600019455,331.170349121094,9.99890232086182,,,0.00356220425901805,0.100746374046957,0.22866007017684,,4,84.6459197998047,1800.68435668945,331.170349121094,
,17840751.891,,13.0320000648499,0.0508036920800805,0,84.1250057220459,9.99890232086182,1814.73449707031,5.51070916652679,264.183906555176,9.99890232086182,,,0.00447970662007623,0.090758846361462,0.725371244743432,,4,84.1250057220459,1814.73449707031,264.183906555176,
,17840900.906,,12.5352699756622,0.120081458240747,0,83.2040519714355,9.99890232086182,1827.86395263672,5.4709587097168,99.4467754364014,9.99890232086182,,,0.00863330044732105,0.0757863239674001,1.3346273481558,,4,83.2040519714355,1827.86395263672,99.4467754364014,
,17841050.078,,12.0377860069275,0.0692777633666992,0,81.0515651702881,9.99890232086182,1837.00942993164,5.44377088546753,0.279628694057465,9.99890232086182,,,0.0233880830726245,0.0421284416749653,0.00813941248036472,,4,81.0515651702881,1837.00942993164,0.279628694057465,
,17841198.797,,11.5430903434753,0.147792562842369,0,68.2549724578857,9.99890232086182,1847.8349609375,5.41202020645142,0.00258079179911874,9.99890232086182,,,0.284280317624092,0.0855587067108043,0.00113698000759793,,4,68.2549724578857,1847.8349609375,0.00258079179911874,
,17841347.656,,11.046196937561,0.161648117005825,0,0.0138959961477667,9.99890232086182,1861.24047851563,5.373082280159,-0.00191696531874186,9.99890232086182,,,0.00121805171201166,0.0933670727098123,0.00124268748173819,,4,0.0138959961477667,1861.24047851563,-0.00191696531874186,
,17841496.891,,10.5486872196198,0.138555524870753,0,0.000432623518463515,9.99890232086182,1874.67712402344,5.33458161354065,-0.00114120492071379,9.99890232086182,,,0.000885447539326647,0.105826864845864,0.000310328206288141,,4,0.000432623518463515,1874.67712402344,-0.00114120492071379,
,17841645.453,,10.0543580055237,0.08313331566751,0,0.00127551634795964,9.99890232086182,1888.95132446289,5.29401838779449,-0.00103676889557391,9.99890232086182,,,0.00185755140729089,0.100967401461567,0.00123636756768369,,4,0.00127551634795964,1888.95132446289,-0.00103676889557391,
,17841795.797,,9.55616068840027,0.101607387885451,0,-0.000745908242606674,9.99890232086182,1903.37551879883,5.25408041477203,-0.000768262420024257,9.99890232086182,,,0.000696519770560604,0.0984969525334766,0.00122589052437939,,4,-0.000745908242606674,1903.37551879883,-0.000768262420024257,
,17841942.5,,9.06068801879883,0.0646592462435365,0,-0.000648923640255816,9.99890232086182,1916.10571289063,5.20745468139648,-0.00120831413005362,9.99890232086182,,,0.000599836716140186,0.0878827833280228,0.00190346597635939,,4,-0.000648923640255816,1916.10571289063,-0.00120831413005362,
,17842091.125,,8.56387114524841,0.106225905939937,0,-0.00206613301998004,9.99890232086182,1925.57632446289,5.19332933425903,-0.00102931754736346,9.99890232086182,,,0.00162723824764274,0.0501663224483981,0.00131829606394888,,4,-0.00206613301998004,1925.57632446289,-0.00102931754736346,
,17842239.859,,8.06955504417419,0.0831333175301552,0,-0.000835418184578884,9.99890232086182,1927.5505065918,5.18570423126221,-0.00202135479776189,9.99890232086182,,,0.000762988641115907,0.033143649407043,0.000498962700887635,,4,-0.000835418184578884,1927.5505065918,-0.00202135479776189,
,17842390.703,,7.57077145576477,0.0230925874784589,0,-0.00105169497692259,9.99890232086182,1900.74850463867,5.18570423126221,-0.00154397630831227,9.99890232086182,,,0.000913858868818341,0.325949648859747,0.00180627480357685,,4,-0.00105169497692259,1900.74850463867,-0.00154397630831227,
,17842537.641,,7.0761786699295,0.0508036920800805,0,-0.00168573917471804,9.99890232086182,1774.98977661133,5.60721063613892,-0.000134264883854485,9.99890232086182,,,0.00046628454128438,1.21768192530174,0.000872298729442247,,4,-0.00168573917471804,1774.98977661133,-0.000134264883854485,
,17842686.938,,6.57882821559906,0.0692777615040541,0,0.000402771374865551,9.99890232086182,1414.91564941406,6.55797529220581,-0.00116358241939452,9.99890232086182,,,0.000846648260328984,2.68305990164803,0.00078628008138126,,4,0.000402771374865551,1414.91564941406,-0.00116358241939452,
,17842835.734,,6.08329749107361,0.0230925879441202,0,-0.00070115326980158,9.99890232086182,778.620468139648,9.7338981628418,-0.00074588495772332,9.99890232086182,,,0.000884676655723037,4.08972060560465,0.00169947565266351,,4,-0.00070115326980158,778.620468139648,-0.00074588495772332,
,17842983.906,,5.58910489082336,0.0692777633666992,0,0.000402771373956057,9.99890232086182,132.440460205078,9.7338981628418,-0.00155147426994517,9.99890232086182,,,0.00044126758285031,2.27915714200478,0.000307917409570209,,4,0.000402771373956057,132.440460205078,-0.00155147426994517,
,17843133.563,,5.08960354328156,0.0738962814211845,0,0.00118598317203578,9.99890232086182,2.06358969211578,9.7338981628418,-3.7303555473045e-005,9.99890232086182,,,0.000281765015230731,0.0296776690788195,0.000750729662316342,,4,0.00118598317203578,2.06358969211578,-3.7303555473045e-005,
,17843281.875,,4.59579360485077,0.0738962809555233,0,-7.45139641367132e-006,9.99890232086182,0.38045009970665,9.7338981628418,-0.00100696330991923,9.99890232086182,,,0.000289532739822825,0.00246527427370236,0.000975833560275178,,4,-7.45139641367132e-006,0.38045009970665,-0.00100696330991923,
,17843431.188,,4.09771001338959,0.101607386022806,0,-0.00199902386520989,9.99890232086182,0.101153984665871,9.7338981628418,2.23774804908317e-005,9.99890232086182,,,0.000560161365792513,0.000977958479773215,0.000579450413668194,,4,-0.00199902386520989,0.101153984665871,2.23774804908317e-005,
,17843580.688,,3.6000412106514,0.0646592453122139,0,0.00083541815274657,9.99890232086182,0.0219976538792253,9.7338981628418,6.71557245368604e-005,9.99890232086182,,,0.00109421179531536,0.00201176789810174,0.000650380849621378,,4,0.00083541815274657,0.0219976538792253,6.71557245368604e-005,
,17843728.641,,3.10670125484467,0.0461851758882403,0,0.000559413736482384,9.99890232086182,0.00347855093423277,9.7338981628418,-0.000484829884953797,9.99890232086182,,,0.00047894609707789,0.000889477504934623,0.00115370577061476,,4,0.000559413736482384,0.00347855093423277,-0.000484829884953797,
,17844755.031,,17.6103911399841,20000.3134765625,0,85.868091583252,9.99890232086182,1690.11856079102,5.60946083068848,353.931938171387,9.99890232086182,,,0.0010839313094579,0.0665000015322427,0.00199760511461168,,4,85.868091583252,1690.11856079102,353.931938171387,
,17844904.344,,17.1141400337219,20000.3828125,0,85.8219242095947,9.99890232086182,1703.05709838867,5.60946083068848,354.089500427246,9.99890232086182,,,0.00107214542001334,0.07787575899362,0.00202032071865708,,4,85.8219242095947,1703.05709838867,354.089500427246,
,17845053.984,,16.6160178184509,20000.419921875,0,85.7643013000488,9.99890232086182,1716.12664794922,5.60946083068848,354.183319091797,9.99890232086182,,,0.00180383557925274,0.074312527288395,0.00143026222600714,,4,85.7643013000488,1716.12664794922,354.183319091797,
,17845202.063,,16.1199927330017,20000.4809570313,0,85.691032409668,9.99890232086182,1729.28604125977,5.60946083068848,354.159034729004,9.99890232086182,,,0.00112699612464388,0.0767722980041658,0.00207074473475424,,4,85.691032409668,1729.28604125977,354.159034729004,
,17845350.984,,15.6261134147644,20000.5263671875,0,85.5985355377197,9.99890232086182,1742.58810424805,5.60946083068848,353.973579406738,9.99890232086182,,,0.00107199610984395,0.0754233222677946,0.00138718674378698,,4,85.5985355377197,1742.58810424805,353.973579406738,
,17845500.594,,15.1264379024506,20000.5361328125,0,85.4772415161133,9.99890232086182,1756.25408935547,5.60946083068848,353.516311645508,9.99890232086182,,,0.00227455782896606,0.0749102303581709,0.00326077858857992,,4,85.4772415161133,1756.25408935547,353.516311645508,
,17845649.406,,14.6323454380035,20000.666015625,0,85.3188781738281,9.99890232086182,1769.92422485352,5.60946083068848,352.54524230957,9.99890232086182,,,0.00103719086246083,0.0744032511529362,0.00793015283713161,,4,85.3188781738281,1769.92422485352,352.54524230957,
,17845798.016,,14.1350374221802,20000.689453125,0,85.1053886413574,9.99890232086182,1783.80868530273,5.60627329349518,350.27880859375,9.99890232086182,,,0.00259032551012288,0.102759582813738,0.0263370854244409,,4,85.1053886413574,1783.80868530273,350.27880859375,
,17845947.094,,13.638787984848,20000.5317382813,0,84.8050956726074,9.99890232086182,1797.9052734375,5.56233513355255,341.728561401367,9.99890232086182,,,0.00309417570727181,0.0884126630353618,0.108239087909123,,4,84.8050956726074,1797.9052734375,341.728561401367,
,17846096.281,,13.1412613391876,20000.5405273438,0,84.3598651885986,9.99890232086182,1812.21459960938,5.51845943927765,305.487701416016,9.99890232086182,,,0.00361436224808843,0.110439265685547,0.44794848477154,,4,84.3598651885986,1812.21459960938,305.487701416016,
,17846245.469,,12.6459398269653,20000.6059570313,0,83.6284427642822,9.99890232086182,1826.50680541992,5.47508370876312,216.149147033691,9.99890232086182,,,0.00597081742481053,0.0949125675850146,0.73924284681903,,4,83.6284427642822,1826.50680541992,216.149147033691,
,17846393.688,,12.1495966911316,20000.60546875,0,82.1547679901123,9.99890232086182,1840.0908203125,5.43458306789398,105.140567779541,9.99890232086182,,,0.0148771856986671,0.0902292027167671,0.654853971385597,,4,82.1547679901123,1840.0908203125,105.140567779541,
,17846542.594,,11.6549875736237,20000.5961914063,0,77.7001037597656,9.99890232086182,1851.04302978516,5.40264511108398,34.5291261672974,9.99890232086182,,,0.0622671329818698,0.0624613940691648,0.302817160305116,,4,77.7001037597656,1851.04302978516,34.5291261672974,
,17846691.547,,11.1580753326416,20000.703125,0,53.9193029403687,9.99890232086182,1860.9775390625,5.37358224391937,8.23872065544128,9.99890232086182,,,0.363696726175252,0.10037665214224,0.106686332780851,,4,53.9193029403687,1860.9775390625,8.23872065544128,
,17846840.609,,10.6613323688507,20000.2036132813,0,8.89031982421875,9.99890232086182,1874.16027832031,5.33601915836334,1.53907307982445,9.99890232086182,,,0.203508960993964,0.116447880360552,0.023273046576845,,4,8.89031982421875,1874.16027832031,1.53907307982445,
,17846989.016,,10.1674764156342,20000.2587890625,0,0.216302216053009,9.99890232086182,1887.96920776367,5.29701864719391,0.23592671006918,9.99890232086182,,,0.00592514455066847,0.0933394732071809,0.00440469609077042,,4,0.216302216053009,1887.96920776367,0.23592671006918,
,17847139.172,,9.66555166244507,20000.2353515625,0,0.000641472230199724,9.99890232086182,1902.37268066406,5.25664305686951,0.0290302513167262,9.99890232086182,,,0.00203917356811963,0.109199451165864,0.00130532526844449,,4,0.000641472230199724,1902.37268066406,0.0290302513167262,
,17847286.766,,8.90131616592407,20000.2631835938,0,-0.000723554057913134,9.99890232086182,1921.45791625977,5.20432960987091,-0.00079061665746849,9.99890232086182,,,0.000602041172983885,1.99011106619158,0.000801818562198939,,4,-0.000723554057913134,1921.45791625977,-0.00079061665746849,
,17847437.688,,8.67860150337219,20000.2768554688,0,-0.000164117046551837,9.99890232086182,1927.94003295898,5.1871417760849,-0.000842869572807103,9.99890232086182,,,0.000268121094964079,0.0715263480589596,0.00107667975501433,,4,-0.000164117046551837,1927.94003295898,-0.000842869572807103,
,17847587.406,,8.17877912521362,20000.2631835938,0,0.000358062941813841,9.99890232086182,1934.93121337891,5.16826641559601,-0.000939830886636628,9.99890232086182,,,0.00177605545287628,0.0175098577051247,0.000879653334696207,,4,0.000358062941813841,1934.93121337891,-0.000939830886636628,
,17847737.625,,7.68398833274841,20000.318359375,0,-5.96810241404455e-005,9.99890232086182,1926.93933105469,5.1677041053772,-0.00102936414259602,9.99890232086182,,,0.00113515576352375,0.135827565958103,0.00148961944797856,,4,-5.96810241404455e-005,1926.93933105469,-0.00102936414259602,
,17847884.281,,7.19068050384521,20000.3037109375,0,0.000939854173338972,9.99890232086182,1862.5676574707,5.1677041053772,-0.000328210797306383,9.99890232086182,,,0.000578711822373405,0.648836939939576,0.00101986664400905,,4,0.000939854173338972,1862.5676574707,-0.000328210797306383,
,17848033.516,,6.69308412075043,20000.3227539063,0,0.00038784524804214,9.99890232086182,1655.53494262695,5.70177483558655,-0.00257331706234254,9.99890232086182,,,0.00125862320914418,1.84864229254249,0.00114807408859338,,4,0.00038784524804214,1655.53494262695,-0.00257331706234254,
,17848182.344,,6.19728517532349,20000.3129882813,0,0.000708604682586156,9.99890232086182,1295.32022094727,7.65099191665649,-0.00095475694979541,9.99890232086182,,,0.00187415013877408,2.13053824730525,0.00166533753919171,,4,0.000708604682586156,1295.32022094727,-0.00095475694979541,
,17848331.781,,5.69879043102264,20000.2719726563,0,-0.000469927072117571,9.99890232086182,897.869079589844,9.68639755249023,-0.00146196433342993,9.99890232086182,,,0.00174423671448748,2.16425366581579,0.000664790757337453,,4,-0.000469927072117571,897.869079589844,-0.00146196433342993,
,17848480.688,,5.20298433303833,20000.2724609375,0,-0.000686227216647239,9.99890232086182,568.305541992188,9.68639755249023,-0.000246128995058825,9.99890232086182,,,0.00145123970703482,1.53505517418157,0.00127413232393661,,4,-0.000686227216647239,568.305541992188,-0.000246128995058825,
,17848629.094,,4.70870041847229,20000.3408203125,0,0.000231226188589062,9.99890232086182,333.98917388916,9.68639755249023,5.96810459683184e-005,9.99890232086182,,,0.00146441300526205,1.04532167847249,0.000224304576738176,,4,0.000231226188589062,333.98917388916,5.96810459683184e-005,
,17848778.656,,4.21041965484619,20000.2905273438,0,-0.000499755943565106,9.99890232086182,180.221042633057,9.68639755249023,-0.0004997559444746,9.99890232086182,,,0.000941683332054983,0.682870947260254,0.0013537012461483,,4,-0.000499755943565106,180.221042633057,-0.0004997559444746,
,17848926.953,,3.71618151664734,20000.3364257813,0,-0.000529608125361847,9.99890232086182,88.0077018737793,9.68639755249023,0.000223751510930015,9.99890232086182,,,0.000458524673879914,0.378443966730042,0.000635158776344133,,4,-0.000529608125361847,88.0077018737793,0.000223751510930015,
,17849075.813,,3.21926659345627,20000.2998046875,0,-2.98521699733101e-005,9.99890232086182,36.5377502441406,9.68639755249023,0.000268506511929445,9.99890232086182,,,0.000742034904808993,0.186153324254362,0.001455702023666,,4,-2.98521699733101e-005,36.5377502441406,0.000268506511929445,
,17850099.234,,17.7245082855225,40000.3720703125,0,85.9085292816162,9.99890232086182,1687.01620483398,5.59021043777466,354.032173156738,9.99890232086182,,,0.00161841538041106,0.0716896494561466,0.00198802463977777,,4,85.9085292816162,1687.01620483398,354.032173156738,
,17850250.313,,17.22398853302,40000.4482421875,0,85.8692359924316,9.99890232086182,1699.98663330078,5.59021043777466,354.242889404297,9.99890232086182,,,0.00109436610657029,0.0761311984881972,0.000778048631834837,,4,85.8692359924316,1699.98663330078,354.242889404297,
,17850398.5,,16.7304110527039,40000.6318359375,0,85.8215217590332,9.99890232086182,1712.94372558594,5.59021043777466,354.39852142334,9.99890232086182,,,0.00151789963107662,0.0747477601171845,0.00154398664265953,,4,85.8215217590332,1712.94372558594,354.39852142334,
,17850547.625,,16.2337894439697,40000.271484375,0,85.7591991424561,9.99890232086182,1726.15051269531,5.59021043777466,354.479347229004,9.99890232086182,,,0.00132244473838477,0.0831850291887597,0.00119611291172369,,4,85.7591991424561,1726.15051269531,354.479347229004,
,17850696.703,,15.7387390136719,40000.3212890625,0,85.681604385376,9.99890232086182,1739.48196411133,5.59021043777466,354.442268371582,9.99890232086182,,,0.00155745615134195,0.0725118399172441,0.000659269750588377,,4,85.681604385376,1739.48196411133,354.442268371582,
,17850845.266,,15.2424287796021,40000.41796875,0,85.581371307373,9.99890232086182,1752.98168945313,5.59021043777466,354.228691101074,9.99890232086182,,,0.000650011429634612,0.0781605639573136,0.0023705082528701,,4,85.581371307373,1752.98168945313,354.228691101074,
,17850995.047,,14.7435991764069,40000.5625,0,85.4505596160889,9.99890232086182,1766.72534179688,5.59021043777466,353.692863464355,9.99890232086182,,,0.00172934473722824,0.079399067466434,0.00401775100616073,,4,85.4505596160889,1766.72534179688,353.692863464355,
,17851143.344,,14.2492029666901,40000.6328125,0,85.2750873565674,9.99890232086182,1780.51489257813,5.59021043777466,352.533409118652,9.99890232086182,,,0.000805621705964768,0.0771673155273967,0.00904256425842721,,4,85.2750873565674,1780.51489257813,352.533409118652,
,17851292.891,,13.7520277500153,40000.248046875,0,85.0372772216797,9.99890232086182,1794.63436889648,5.57221031188965,349.591537475586,9.99890232086182,,,0.000865238597635682,0.0948189501177739,0.0330772080947569,,4,85.0372772216797,1794.63436889648,349.591537475586,
,17851442.078,,13.2532403469086,40000.3310546875,0,84.692024230957,9.99890232086182,1809.05987548828,5.52802205085754,337.800895690918,9.99890232086182,,,0.00217376164868515,0.114511339010344,0.186850007728655,,4,84.692024230957,1809.05987548828,337.800895690918,
,17851590.891,,12.7581465244293,40000.3173828125,0,84.1589946746826,9.99890232086182,1823.55422973633,5.48383390903473,292.955574035645,9.99890232086182,,,0.00513053489354863,0.106948864512716,0.526903299831023,,4,84.1589946746826,1823.55422973633,292.955574035645,
,17851739.172,,12.2639989852905,40000.447265625,0,83.236307144165,9.99890232086182,1838.18200683594,5.4404581785202,202.608104705811,9.99890232086182,,,0.00867462892121044,0.0867511637139663,0.644934547329761,,4,83.236307144165,1838.18200683594,202.608104705811,
,17851887.828,,11.7684106826782,40000.4931640625,0,81.1893482208252,9.99890232086182,1852.37582397461,5.39877009391785,104.631399154663,9.99890232086182,,,0.0222732371823921,0.0880760092119964,0.550104086219683,,4,81.1893482208252,1852.37582397461,104.631399154663,
,17852037.156,,11.2707588672638,40000.53515625,0,74.4483089447021,9.99890232086182,1864.36288452148,5.36401963233948,40.1779098510742,9.99890232086182,,,0.0825690213073056,0.0724381822396769,0.2859024367935,,4,74.4483089447021,1864.36288452148,40.1779098510742,
,17852186.188,,10.7728848457336,40000.63671875,0,47.0522613525391,9.99890232086182,1874.41848754883,5.33514416217804,11.9670889377594,9.99890232086182,,,0.275726117478125,0.0720424492274371,0.0999841471417576,,4,47.0522613525391,1874.41848754883,11.9670889377594,
,17852335,,10.278288602829,40000.650390625,0,7.70815181732178,9.99890232086182,1887.58929443359,5.2978310585022,2.92399936914444,9.99890232086182,,,0.14788207575232,0.0986747463711615,0.0308520184267584,,4,7.70815181732178,1887.58929443359,2.92399936914444,
,17852483.078,,9.78290605545044,40000.6875,0,0.247331444174051,9.99890232086182,1902.0830078125,5.25770533084869,0.596134468913078,9.99890232086182,,,0.00633172144116157,0.0912885592915643,0.0062610289091145,,4,0.247331444174051,1902.0830078125,0.596134468913078,
,17852633.797,,9.28420686721802,40000.517578125,0,0.00149174665602914,9.99890232086182,1916.92172241211,5.21689224243164,0.0997485872358084,9.99890232086182,,,0.00143631068156613,0.0863815183495146,0.000939532022658891,,4,0.00149174665602914,1916.92172241211,0.0997485872358084,
,17852782.859,,8.79049587249756,40000.51171875,0,-0.00120836064161267,9.99890232086182,1931.33764648438,5.17807924747467,0.0127174879889935,9.99890232086182,,,0.000195077023082304,0.0979381688161481,0.00114438303398157,,4,-0.00120836064161267,1931.33764648438,0.0127174879889935,
,17852932.422,,8.29230570793152,40000.5263671875,0,-0.000716079368430655,9.99890232086182,1943.54699707031,5.14539134502411,-0.000671347661409527,9.99890232086182,,,0.00141096628675944,0.0646603460954949,0.00162961177954734,,4,-0.000716079368430655,1943.54699707031,-0.000671347661409527,
,17853081.156,,7.79952645301819,40000.4033203125,0,-0.000783188515924849,9.99890232086182,1949.69192504883,5.12920331954956,-0.00121581203347887,9.99890232086182,,,0.00132866276456127,0.00492639167869393,0.00131487754560099,,4,-0.000783188515924849,1949.69192504883,-0.00121581203347887,
,17853230.047,,7.30242085456848,40000.521484375,0,-2.23774950427469e-005,9.99890232086182,1934.83715820313,5.12920331954956,-0.000522133450431284,9.99890232086182,,,0.00102910396556299,0.224875781419975,0.00157231360501601,,4,-2.23774950427469e-005,1934.83715820313,-0.000522133450431284,
,17853379.125,,6.80384695529938,40000.484375,0,0.000596694015257526,9.99890232086182,1848.15899658203,5.12920331954956,-0.0017081166151911,9.99890232086182,,,0.000747389025732228,0.851441683204302,0.00230100313341607,,4,0.000596694015257526,1848.15899658203,-0.0017081166151911,
,17853527.438,,6.30889177322388,40000.5439453125,0,-0.000954733698563359,9.99890232086182,1631.21304321289,6.00046682357788,-0.000790663223597221,9.99890232086182,,,0.00140689350238239,1.63393710475225,0.00097196215848223,,4,-0.000954733698563359,1631.21304321289,-0.000790663223597221,
,17853676.781,,5.81224226951599,40000.5537109375,0,-0.0001864945388661,9.99890232086182,1311.88775634766,7.59574127197266,-0.00151414741412736,9.99890232086182,,,0.000752522203227833,1.82159545100819,0.000402708913302175,,4,-0.0001864945388661,1311.88775634766,-0.00151414741412736,
,17853825,,5.31722521781921,40000.544921875,0,-0.000462475698441267,9.99890232086182,972.340301513672,9.6163969039917,-0.0013873805073672,9.99890232086182,,,0.000890463968513831,1.89674206882426,0.00209790797991261,,4,-0.000462475698441267,972.340301513672,-0.0013873805073672,
,17853974.406,,4.82021152973175,40000.5390625,0,-0.000947328873735387,9.99890232086182,670.187103271484,9.6163969039917,-0.000507230637595057,9.99890232086182,,,0.00158544395068726,1.69999324506012,0.000873461210478212,,4,-0.000947328873735387,670.187103271484,-0.000507230637595057,
,17854123.125,,4.32425427436829,40000.5703125,0,-9.69613138295244e-005,9.99890232086182,430.728324890137,9.6163969039917,-4.47549646196421e-005,9.99890232086182,,,0.000888685562567061,1.24072414294048,0.000812869950553738,,4,-9.69613138295244e-005,430.728324890137,-4.47549646196421e-005,
,17854272.219,,3.8276738524437,40000.5341796875,0,-0.000798091332399054,9.99890232086182,255.241901397705,9.6163969039917,-0.00109644995245617,9.99890232086182,,,0.000980143037637013,0.816853103038594,0.000559108099631629,,4,-0.000798091332399054,255.241901397705,-0.00109644995245617,
,17854420.406,,3.33346736431122,40000.5400390625,0,0.00021630014089169,9.99890232086182,135.296936035156,9.6163969039917,8.94866534508765e-005,9.99890232086182,,,0.00135226826657223,0.482844611402294,0.0014492713571964,,4,0.00021630014089169,135.296936035156,8.94866534508765e-005,
,17855448.141,,17.8332929611206,60000.5087890625,0,85.9537944793701,9.99890232086182,1683.55374145508,5.54620981216431,354.155937194824,9.99890232086182,,,0.000772122902789546,0.0768683637200828,0.00269863882266384,,4,85.9537944793701,1683.55374145508,354.155937194824,
,17855598.406,,17.3400845527649,60000.4521484375,0,85.9247512817383,9.99890232086182,1696.3014831543,5.54620981216431,354.414253234863,9.99890232086182,,,0.000658253619693695,0.0723130032164128,0.00123443037675426,,4,85.9247512817383,1696.3014831543,354.414253234863,
,17855747.594,,16.8425207138062,60000.6708984375,0,85.8859691619873,9.99890232086182,1709.35354614258,5.54620981216431,354.647453308105,9.99890232086182,,,0.000980330811230691,0.0737956371680093,0.00116315117788348,,4,85.8859691619873,1709.35354614258,354.647453308105,
,17855896.063,,16.3480706214905,60000.369140625,0,85.837532043457,9.99890232086182,1722.49798583984,5.54620981216431,354.82292175293,9.99890232086182,,,0.000880939066637872,0.077773375767406,0.00166837955660036,,4,85.837532043457,1722.49798583984,354.82292175293,
,17856044.969,,15.8508667945862,60000.537109375,0,85.7760372161865,9.99890232086182,1735.77947998047,5.54620981216431,354.92652130127,9.99890232086182,,,0.000690457570613661,0.07030431381891,0.000466517356756911,,4,85.7760372161865,1735.77947998047,354.92652130127,
,17856194.469,,15.3543572425842,60000.6533203125,0,85.6951560974121,9.99890232086182,1749.24444580078,5.54620981216431,354.930862426758,9.99890232086182,,,0.00069285866630114,0.0751084903992694,0.00112014478468219,,4,85.6951560974121,1749.24444580078,354.930862426758,
,17856343.141,,14.8585727214813,60000.537109375,0,85.5933685302734,9.99890232086182,1762.90383911133,5.54620981216431,354.759262084961,9.99890232086182,,,0.0020275394082517,0.070103407278714,0.00146317386813643,,4,85.5933685302734,1762.90383911133,354.759262084961,
,17856492.656,,14.3604156970978,60000.2666015625,0,85.4593353271484,9.99890232086182,1776.81134033203,5.54620981216431,354.284805297852,9.99890232086182,,,0.0021535106388846,0.0752657523238277,0.00246168299388432,,4,85.4593353271484,1776.81134033203,354.284805297852,
,17856641.484,,13.8645594120026,60000.396484375,0,85.2784175872803,9.99890232086182,1790.87503051758,5.54620981216431,353.191879272461,9.99890232086182,,,0.00276981895394866,0.0888085381361093,0.0101594319310877,,4,85.2784175872803,1790.87503051758,353.191879272461,
,17856790.844,,13.3671350479126,60000.52734375,0,85.0222206115723,9.99890232086182,1805.19073486328,5.53964722156525,350.40372467041,9.99890232086182,,,0.00172873140728526,0.10790026520152,0.0355544871718262,,4,85.0222206115723,1805.19073486328,350.40372467041,
,17856938.688,,12.8736119270325,60000.638671875,0,84.6526412963867,9.99890232086182,1819.69924926758,5.49570906162262,339.84986114502,9.99890232086182,,,0.00155589151605444,0.0909336725966563,0.1324073125472,,4,84.6526412963867,1819.69924926758,339.84986114502,
,17857088.094,,12.3770785331726,60000.234375,0,84.0485610961914,9.99890232086182,1834.55773925781,5.4509584903717,296.096015930176,9.99890232086182,,,0.00464235648832602,0.0936338579471998,0.454204168507518,,4,84.0485610961914,1834.55773925781,296.096015930176,
,17857236.609,,11.8820803165436,60000.3369140625,0,82.9438190460205,9.99890232086182,1849.65518188477,5.4064576625824,206.717990875244,9.99890232086182,,,0.0110450768278077,0.100828946640649,0.696807672988595,,4,82.9438190460205,1849.65518188477,206.717990875244,
,17857386.359,,11.381906747818,60000.3505859375,0,80.2994785308838,9.99890232086182,1864.81610107422,5.36276948451996,110.640815734863,9.99890232086182,,,0.0291306610484115,0.101047549207593,0.573101273050166,,4,80.2994785308838,1864.81610107422,110.640815734863,
,17857534.938,,10.8877620697021,60000.4990234375,0,71.2985324859619,9.99890232086182,1878.45010375977,5.32358145713806,46.8863306045532,9.99890232086182,,,0.123721030774884,0.0996461828328899,0.36940312883935,,4,71.2985324859619,1878.45010375977,46.8863306045532,
,17857683.766,,10.3907270431519,60000.6162109375,0,39.9368324279785,9.99890232086182,1889.29064941406,5.29326844215393,16.0157389640808,9.99890232086182,,,0.246890042015227,0.0664508333329015,0.116713404982683,,4,39.9368324279785,1889.29064941406,16.0157389640808,
,17857828.094,,9.90116238594055,60000.6376953125,0,5.69408345222473,9.99890232086182,1901.8132019043,5.25833034515381,4.64107298851013,9.99890232086182,,,0.0715509887567332,0.0461455954720658,0.0248477137215876,,4,5.69408345222473,1901.8132019043,4.64107298851013,
,17857981.984,,9.39479780197144,60000.6904296875,0,0.179850321263075,9.99890232086182,1917.15521240234,5.21645474433899,1.10312709212303,9.99890232086182,,,0.0086597020886452,0.141491617073231,0.0157953996182314,,4,0.179850321263075,1917.15521240234,1.10312709212303,
,17858131.875,,8.90334177017212,60000.435546875,0,0.000835418174574443,9.99890232086182,1932.78283691406,5.17245435714722,0.227938130497932,9.99890232086182,,,0.00126496193652184,0.0876205108325237,0.00280736292917519,,4,0.000835418174574443,1932.78283691406,0.227938130497932,
,17858280.938,,8.40532064437866,60000.490234375,0,0.000462475698441267,9.99890232086182,1948.66955566406,5.13176608085632,0.0374066717922688,9.99890232086182,,,0.00222997774157282,0.108056293112932,0.00066628115617574,,4,0.000462475698441267,1948.66955566406,0.0374066717922688,
,17858426.594,,7.90893292427063,60000.48046875,0,-0.000738433573133079,9.99890232086182,1962.67666625977,5.09532785415649,0.00493783212732524,9.99890232086182,,,0.000349481905005087,0.0724267645093727,0.000746023139460502,,4,-0.000738433573133079,1962.67666625977,0.00493783212732524,
,17858578.953,,7.4140020608902,60000.52734375,0,-0.000559436999537866,9.99890232086182,1971.08108520508,5.07345247268677,-0.000738410275516799,9.99890232086182,,,0.00101754565891714,0.0159584175077348,0.00066528415440535,,4,-0.000559436999537866,1971.08108520508,-0.000738410275516799,
,17858728,,6.91710698604584,60000.6162109375,0,0.000328187502418587,9.99890232086182,1958.77020263672,5.07295274734497,-0.000753359692680533,9.99890232086182,,,0.00257409700364097,0.188821851857363,0.00132042060531589,,4,0.000328187502418587,1958.77020263672,-0.000753359692680533,
,17858876.719,,6.42061710357666,60000.642578125,0,0.000179019814822823,9.99890232086182,1877.63995361328,5.07295274734497,-0.000835394908790477,9.99890232086182,,,0.00132272508984639,0.835845989049157,0.00141822030700821,,4,0.000179019814822823,1877.63995361328,-0.000835394908790477,
,17859025.047,,5.92611467838287,60000.6669921875,0,-0.0013202247209847,9.99890232086182,1683.31509399414,5.9334659576416,-0.00255839104647748,9.99890232086182,,,0.00137977083990155,1.42133435873959,0.00117661008970743,,4,-0.0013202247209847,1683.31509399414,-0.00255839104647748,
,17859173.828,,5.43053376674652,60000.685546875,0,4.47549464297481e-005,9.99890232086182,1399.66940307617,6.94198131561279,-0.00238686916418374,9.99890232086182,,,0.00103212876467883,1.8425732538245,0.000699400558781279,,4,4.47549464297481e-005,1399.66940307617,-0.00238686916418374,
,17859322.625,,4.93466520309448,60000.642578125,0,-0.000447526352218119,9.99890232086182,1087.42639160156,8.78638362884521,-0.00127546978546889,9.99890232086182,,,0.00139671906380199,1.8032781642507,0.00167513447084225,,4,-0.000447526352218119,1087.42639160156,-0.00127546978546889,
,17859472.156,,4.43611681461334,60000.6572265625,0,0.000425172125687823,9.99890232086182,791.359237670898,9.50889492034912,-0.00039529666537419,9.99890232086182,,,0.00126078750776059,1.49417456630415,0.000637614302640963,,4,0.000425172125687823,791.359237670898,-0.00039529666537419,
,17859620.938,,3.94061559438705,60000.6513671875,0,5.96577774558682e-005,9.99890232086182,537.954467773438,9.50889492034912,-0.000186471240340325,9.99890232086182,,,0.000974348112344707,1.27706607883244,0.000473789936267414,,4,5.96577774558682e-005,537.954467773438,-0.000186471240340325,
,17859769.688,,3.44442480802536,60000.240234375,0,0.00095473368128296,9.99890232086182,334.933853149414,9.50889492034912,-7.45605684642214e-005,9.99890232086182,,,0.000933302623765307,0.970007277033695,0.000854506395013792,,4,0.00095473368128296,334.933853149414,-7.45605684642214e-005,
,17860803.703,,17.9098305702209,80000.642578125,0,86.0038661956787,9.99890232086182,1679.97985839844,5.931715965271,354.268737792969,9.99890232086182,,,0.0011793323381485,0.438825268986559,0.0118803367731838,,4,86.0038661956787,1679.97985839844,354.268737792969,
,17860948.188,,17.4530553817749,80000.51953125,0,85.9807968139648,9.99890232086182,1692.38934326172,5.90915286540985,354.575553894043,9.99890232086182,,,0.000451393306361085,0.104005679263194,0.00220566046604791,,4,85.9807968139648,1692.38934326172,354.575553894043,
,17861098.594,,16.9545340538025,80000.19140625,0,85.9527339935303,9.99890232086182,1705.357421875,5.86396479606628,354.864242553711,9.99890232086182,,,0.000653068484501738,0.086245375453975,0.00138334198960024,,4,85.9527339935303,1705.357421875,354.864242553711,
,17861246.563,,16.4596176147461,80000.42578125,0,85.9170894622803,9.99890232086182,1718.43511962891,5.81952655315399,355.121757507324,9.99890232086182,,,0.00115312909938292,0.0949651525292432,0.000243543849174688,,4,85.9170894622803,1718.43511962891,355.121757507324,
,17861395.563,,15.9646859169006,80000.673828125,0,85.8697204589844,9.99890232086182,1731.66006469727,5.775151014328,355.339561462402,9.99890232086182,,,0.00197159704485798,0.0940978580298337,0.00200702385591071,,4,85.8697204589844,1731.66006469727,355.339561462402,
,17861544.797,,15.4678583145142,80000.7109375,0,85.8094902038574,9.99890232086182,1745.14205932617,5.73052513599396,355.495719909668,9.99890232086182,,,0.00212053596357204,0.0891739873196434,0.00135801079550988,,4,85.8094902038574,1745.14205932617,355.495719909668,
,17861693.328,,14.97123503685,80000.39453125,0,85.7315578460693,9.99890232086182,1758.69546508789,5.68602454662323,355.56470489502,9.99890232086182,,,0.00121539122457254,0.113501215996247,0.000940707748914319,,4,85.7315578460693,1758.69546508789,355.56470489502,
,17861842.328,,14.4748153686523,80000.62109375,0,85.6302947998047,9.99890232086182,1772.44116210938,5.6420236825943,355.488441467285,9.99890232086182,,,0.0021093930689603,0.0811877250433336,0.00208809991524474,,4,85.6302947998047,1772.44116210938,355.488441467285,
,17861991.734,,13.9780874252319,80000.560546875,0,85.4952220916748,9.99890232086182,1786.44784545898,5.59777319431305,355.168128967285,9.99890232086182,,,0.000663326935063941,0.102002853564885,0.00409489583721578,,4,85.4952220916748,1786.44784545898,355.168128967285,
,17862140.094,,13.483056306839,80000.7265625,0,85.311279296875,9.99890232086182,1800.66665649414,5.55358493328094,354.339462280273,9.99890232086182,,,0.00333475240722875,0.0893804119295548,0.0089687029317292,,4,85.311279296875,1800.66665649414,354.339462280273,
,17862290.016,,12.9835538864136,80000.3125,0,85.0506019592285,9.99890232086182,1815.29180908203,5.50877165794373,352.176330566406,9.99890232086182,,,0.00265948973248094,0.120911568835989,0.0274715756638133,,4,85.0506019592285,1815.29180908203,352.176330566406,
,17862438.313,,12.4896805286407,80000.4609375,0,84.6609992980957,9.99890232086182,1830.10922241211,5.46445870399475,344.834030151367,9.99890232086182,,,0.00320233554459219,0.0938061456640831,0.0902979000151037,,4,84.6609992980957,1830.10922241211,344.834030151367,
,17862586.766,,11.9950768947601,80000.58984375,0,84.0128421783447,9.99890232086182,1845.27313232422,5.41952049732208,311.828269958496,9.99890232086182,,,0.00491572959724334,0.0833769947153679,0.301565726705661,,4,84.0128421783447,1845.27313232422,311.828269958496,
,17862736.109,,11.4982974529266,80000.634765625,0,82.7452774047852,9.99890232086182,1860.77786254883,5.37414479255676,227.445659637451,9.99890232086182,,,0.0137800182235498,0.112883044684641,0.763895627278442,,4,82.7452774047852,1860.77786254883,227.445659637451,
,17862885.641,,10.998943567276,80000.54296875,0,79.4799995422363,9.99890232086182,1876.69085693359,5.32858157157898,129.470001220703,9.99890232086182,,,0.0410836337505623,0.117373779380919,0.652955589660016,,4,79.4799995422363,1876.69085693359,129.470001220703,
,17863033.891,,10.5058455467224,80000.642578125,0,68.0908718109131,9.99890232086182,1892.05627441406,5.28533089160919,59.951473236084,9.99890232086182,,,0.126038374260526,0.0906148247103676,0.310846967328355,,4,68.0908718109131,1892.05627441406,59.951473236084,
,17863182.547,,10.0068476200104,80000.2421875,0,32.7859907150269,9.99890232086182,1905.24230957031,5.2487678527832,22.9265441894531,9.99890232086182,,,0.276603199801905,0.0685711984776003,0.153413580663535,,4,32.7859907150269,1905.24230957031,22.9265441894531,
,17863330.016,,9.49894499778748,80000.388671875,0,3.65327626466751,9.99890232086182,1917.50942993164,5.21507978439331,7.27743828296661,9.99890232086182,,,0.135646868627909,0.184819862659457,0.116517757400069,,4,3.65327626466751,1917.50942993164,7.27743828296661,
,17863477.453,,9.01482748985291,80000.45703125,0,0.128323836252093,9.99890232086182,1932.47033691406,5.16045379638672,2.09076702594757,9.99890232086182,,,0.00335348540210881,0.0960024221358114,0.0157125163871042,,4,0.128323836252093,1932.47033691406,2.09076702594757,
,17863624.359,,8.51909613609314,80000.50390625,0,0.000947305561567191,9.99890232086182,1949.43371582031,5.13001596927643,0.502912491559982,9.99890232086182,,,0.00109833984861073,0.135821833674701,0.00606276344286716,,4,0.000947305561567191,1949.43371582031,0.502912491559982,
,17863774.281,,8.0213029384613,80000.541015625,0,-0.000328187481500208,9.99890232086182,1967.03359985352,5.08376526832581,0.0990101750940084,9.99890232086182,,,0.00134540782397088,0.1391549996207,0.00153391117596243,,4,-0.000328187481500208,1967.03359985352,0.0990101750940084,
,17863923.797,,7.52591705322266,80000.625,0,-0.00026855303440243,9.99890232086182,1983.95504760742,5.0407646894455,0.0151342323515564,9.99890232086182,,,0.00157069340671835,0.112260274812692,0.00169305870840172,,4,-0.00026855303440243,1983.95504760742,0.0151342323515564,
,17864071.922,,7.030144572258,80000.634765625,0,-5.22296322742477e-005,9.99890232086182,1997.05053710938,5.00745153427124,0.0016633849372738,9.99890232086182,,,0.000813875681616041,0.0644025315049286,0.00141449147302004,,4,-5.22296322742477e-005,1997.05053710938,0.0016633849372738,
,17864220.75,,6.53452563285828,80000.650390625,0,-0.000768239156968775,9.99890232086182,1995.54885864258,5.00095129013062,-0.00088762453833624,9.99890232086182,,,0.000396026426886622,0.100796465316588,0.00109040949138953,,4,-0.000768239156968775,1995.54885864258,-0.00088762453833624,
,17864369.359,,6.03812801837921,80000.6640625,0,-0.000596740565924847,9.99890232086182,1939.21392822266,5.00095129013062,-0.000842869569169125,9.99890232086182,,,0.000720083649932615,0.669689418956412,0.000627074103593375,,4,-0.000596740565924847,1939.21392822266,-0.000842869569169125,
,17864518.094,,5.54321324825287,80000.6796875,0,-0.000380417171982117,9.99890232086182,1783.3796081543,5.40895795822144,-0.00176029971680691,9.99890232086182,,,0.000920196334000918,1.19043614453825,0.00197063069155825,,4,-0.000380417171982117,1783.3796081543,-0.00176029971680691,
,17864667.344,,5.04630279541016,80000.2109375,0,-0.000574339814193081,9.99890232086182,1538.81051635742,6.3249716758728,-0.000783188538662216,9.99890232086182,,,0.0010967389344914,1.35219625370292,0.000964107847389602,,4,-0.000574339814193081,1538.81051635742,-0.000783188538662216,
,17864816.656,,4.54860842227936,80000.22265625,0,0.000507230633957079,9.99890232086182,1251.11053466797,7.55292820930481,-0.00210339002660476,9.99890232086182,,,0.000987979754675199,1.65592315548293,0.00102696503954525,,4,0.000507230633957079,1251.11053466797,-0.00210339002660476,
,17864965.125,,4.05356550216675,80000.294921875,0,0.000798091318756633,9.99890232086182,956.5419921875,9.37389278411865,-0.000827943506010342,9.99890232086182,,,0.000522481574310412,1.56016718944655,0.00147894846263329,,4,0.000798091318756633,956.5419921875,-0.000827943506010342,
,17865114.109,,3.55757230520248,80000.2890625,0,0.000193922620383091,9.99890232086182,680.64030456543,9.37389278411865,-0.00142466076795245,9.99890232086182,,,0.00105747379022584,1.44145431953682,0.00102497515045948,,4,0.000193922620383091,680.64030456543,-0.00142466076795245,
,17865262.719,,3.06240969896317,80000.29296875,0,0.000104435977846151,9.99890232086182,439.936531066895,9.37389278411865,-0.000619071506662294,9.99890232086182,,,0.00130057889766014,1.28419403321535,0.00150508387568334,,4,0.000104435977846151,439.936531066895,-0.000619071506662294,
,17866286.938,,17.5632042884827,100000.298828125,0,86.0369033813477,9.99890232086182,1688.07971191406,5.8497142791748,354.698287963867,9.99890232086182,,,0.0010415171476185,0.0742031382152861,0.00272970311368376,,4,86.0369033813477,1688.07971191406,354.698287963867,
,17866435.938,,17.0677065849304,100000.478515625,0,86.0176200866699,9.99890232086182,1700.94107055664,5.8497142791748,355.033477783203,9.99890232086182,,,0.00201023687833107,0.0732035407784297,0.00220202883376569,,4,86.0176200866699,1700.94107055664,355.033477783203,
,17866584.125,,16.573784828186,100000.525390625,0,85.9911441802979,9.99890232086182,1713.9284362793,5.83477675914764,355.348960876465,9.99890232086182,,,0.000997751188778544,0.0797871385138993,0.0024432532952972,,4,85.9911441802979,1713.9284362793,355.348960876465,
,17866733.156,,16.0782618522644,100000.3671875,0,85.9580364227295,9.99890232086182,1727.12762451172,5.79027605056763,355.63850402832,9.99890232086182,,,0.00106231442609816,0.083642151447907,0.00168945874781031,,4,85.9580364227295,1727.12762451172,355.63850402832,
,17866882.438,,15.5812909603119,100000.537109375,0,85.913537979126,9.99890232086182,1740.44036865234,5.74571287631989,355.909461975098,9.99890232086182,,,0.000380070025775765,0.0906939088343282,0.00190708921575688,,4,85.913537979126,1740.44036865234,355.909461975098,
,17867031.25,,15.0844864845276,100000.296875,0,85.8562107086182,9.99890232086182,1753.96334838867,5.70139968395233,356.126251220703,9.99890232086182,,,0.00180326170786074,0.097227543151189,0.00224226334739291,,4,85.8562107086182,1753.96334838867,356.126251220703,
,17867180.813,,14.5853395462036,100000.44921875,0,85.7832260131836,9.99890232086182,1767.74011230469,5.65721154212952,356.283546447754,9.99890232086182,,,0.001726815322235,0.0805280651991912,0.00115390651414903,,4,85.7832260131836,1767.74011230469,356.283546447754,
,17867328.813,,14.0939698219299,100000.580078125,0,85.6871280670166,9.99890232086182,1781.48895263672,5.61327338218689,356.323661804199,9.99890232086182,,,0.00213064673102047,0.102403878610281,0.000680471852883448,,4,85.6871280670166,1781.48895263672,356.323661804199,
,17867479.016,,13.5915920734406,100000.306640625,0,85.5554332733154,9.99890232086182,1795.82321166992,5.5688351392746,356.184188842773,9.99890232086182,,,0.00212456635272522,0.0988070158220725,0.00309903714403014,,4,85.5554332733154,1795.82321166992,356.184188842773,
,17867626.984,,13.1002490520477,100000.435546875,0,85.3735237121582,9.99890232086182,1810.17864990234,5.52464699745178,355.66788482666,9.99890232086182,,,0.00251321971916262,0.109062514783317,0.00637723833734411,,4,85.3735237121582,1810.17864990234,355.66788482666,
,17867776.375,,12.6013779640198,100000.642578125,0,85.1130313873291,9.99890232086182,1825.00827026367,5.47977137565613,354.231689453125,9.99890232086182,,,0.00249686069540191,0.121574842094915,0.0179984774566493,,4,85.1130313873291,1825.00827026367,354.231689453125,
,17867925.688,,12.1043546199799,100000.505859375,0,84.7086505889893,9.99890232086182,1840.10598754883,5.43452060222626,349.68660736084,9.99890232086182,,,0.0042486356698514,0.101396732581686,0.0586982406304153,,4,84.7086505889893,1840.10598754883,349.68660736084,
,17868073.938,,11.6102657318115,100000.64453125,0,84.0292129516602,9.99890232086182,1855.57144165039,5.38951992988586,330.10619354248,9.99890232086182,,,0.0061469440379239,0.111713391122138,0.26132883944845,,4,84.0292129516602,1855.57144165039,330.10619354248,
,17868223.688,,11.1108679771423,100000.234375,0,82.6064128875732,9.99890232086182,1871.54815673828,5.34320664405823,262.268516540527,9.99890232086182,,,0.0170485964139093,0.121085520433918,0.719027438590876,,4,82.6064128875732,1871.54815673828,262.268516540527,
,17868371.891,,10.6165030002594,100000.376953125,0,78.7596378326416,9.99890232086182,1887.91714477539,5.29689347743988,163.00484085083,9.99890232086182,,,0.0414276605591748,0.108132056539343,0.610425276155457,,4,78.7596378326416,1887.91714477539,163.00484085083,
,17868520.844,,10.1212949752808,100000.458984375,0,64.8506126403809,9.99890232086182,1904.66418457031,5.25064289569855,82.3273696899414,9.99890232086182,,,0.172180028259163,0.118550731963734,0.457712298212558,,4,64.8506126403809,1904.66418457031,82.3273696899414,
,17868669.406,,9.6228883266449,100000.5390625,0,27.5389428138733,9.99890232086182,1920.5703125,5.20707964897156,35.1881103515625,9.99890232086182,,,0.29101048200183,0.102175731914579,0.226725784413487,,4,27.5389428138733,1920.5703125,35.1881103515625,
,17868811.297,,9.01941728591919,100000.580078125,0,1.4376834332943,9.99890232086182,1936.81903076172,5.15420389175415,10.2950456142426,9.99890232086182,,,0.202203821236667,0.585596000972212,0.491732309323372,,4,1.4376834332943,1936.81903076172,10.2950456142426,
,17868969.391,,8.63190126419067,100000.4609375,0,0.0965263210237026,9.99890232086182,1948.10565185547,5.13323473930359,4.19331192970276,9.99890232086182,,,0.00353000082293657,0.103438456579896,0.0322227175637887,,4,0.0965263210237026,1948.10565185547,4.19331192970276,
,17869117.891,,8.13665533065796,100000.4921875,0,0.000141692988108844,9.99890232086182,1965.81384277344,5.08726537227631,1.16414877772331,9.99890232086182,,,0.000756671685972174,0.135612563121147,0.012709742975129,,4,0.000141692988108844,1965.81384277344,1.16414877772331,
,17869268.328,,7.63942337036133,100000.56640625,0,-6.71324451104738e-005,9.99890232086182,1985.1774597168,5.03738951683044,0.270305007696152,9.99890232086182,,,0.000991451190824751,0.128715037365971,0.00354457435317313,,4,-6.71324451104738e-005,1985.1774597168,0.270305007696152,
,17869416.453,,7.14232814311981,100000.59765625,0,8.20818104330101e-005,9.99890232086182,2005.13961791992,4.98720133304596,0.0497586913406849,9.99890232086182,,,0.000312522305595399,0.141443318703502,0.00143638668804194,,4,8.20818104330101e-005,2005.13961791992,0.0497586913406849,
,17869564.953,,6.64763629436493,100000.560546875,0,0.0005370362305257,9.99890232086182,2023.80416870117,4.94145059585571,0.00665337685495615,9.99890232086182,,,0.00130170414773523,0.106024140758795,0.00125168025430247,,4,0.0005370362305257,2023.80416870117,0.00665337685495615,
,17869714.094,,6.15091335773468,100000.626953125,0,-0.000313284731419117,9.99890232086182,2035.34094238281,4.91338777542114,-0.00132022480102023,9.99890232086182,,,0.000955092011506057,0.00787660997070343,0.00103232095601452,,4,-0.000313284731419117,2035.34094238281,-0.00132022480102023,
,17869862.406,,5.6552711725235,100000.21484375,0,0.000358016428435803,9.99890232086182,2012.39981079102,4.91320037841797,-0.00176777437991404,9.99890232086182,,,0.00170688306971939,0.319326084171599,0.00112933233731692,,4,0.000358016428435803,2012.39981079102,-0.00176777437991404,
,17870011.75,,5.1581734418869,100000.310546875,0,-0.000872698450621101,9.99890232086182,1906.52444458008,4.91320037841797,-0.00140228329382808,9.99890232086182,,,0.000676206511726961,0.840412193145514,0.000910127064807777,,4,-0.000872698450621101,1906.52444458008,-0.00140228329382808,
,17870160.281,,4.6627289056778,100000.37109375,0,0.000201397317141527,9.99890232086182,1712.05349731445,5.7469630241394,-0.00192441672697896,9.99890232086182,,,0.000850268498890256,1.23628395199017,0.000985183458436524,,4,0.000201397317141527,1712.05349731445,-0.00192441672697896,
,17870309.859,,4.1647344827652,100000.306640625,0,0.00104424360688427,9.99890232086182,1452.5344543457,6.71947765350342,-0.00243157747900113,9.99890232086182,,,0.000796972645016771,1.54025323034157,0.000917056905979849,,4,0.00104424360688427,1452.5344543457,-0.00243157747900113,
,17870458,,3.67088276147842,100000.419921875,0,-0.00076826244185213,9.99890232086182,1162.81967163086,8.50638008117676,-0.00136500303051434,9.99890232086182,,,0.000970793076940179,1.60394755544631,0.000858120453997839,,4,-0.00076826244185213,1162.81967163086,-0.00136500303051434,
,17870606.859,,3.17531234025955,100000.431640625,0,-9.69846296356991e-005,9.99890232086182,863.089874267578,9.96640205383301,-0.00106659778975882,9.99890232086182,,,0.00152327410154987,1.61502814302479,0.00173837127295577,,4,-9.69846296356991e-005,863.089874267578,-0.00106659778975882,
,17870654.391,,3.01688885688782,100000.38671875,0,4.47549500677269e-005,9.99890232086182,768.701187133789,9.96640205383301,-0.000462475691165309,9.99890232086182,,,0.00131505582056799,1.56461248251458,0.00116062406197277,,4,4.47549500677269e-005,768.701187133789,-0.000462475691165309,